Workbook

Sheet Invoer
B1: van Heugten Transport tarieven Calculator 2026
B2: Deze tarieven zijn geldig van 1 januari t/m 30 juni 2026 | E2: ORDERS AANMELDEN VOOR 15.00 uur
B5: Tariefsaanvraag | C5: =IF(J3="","",J3) | D5: =IF(NOT(ISBLANK(J1)), VLOOKUP(J1, Stamdata!H:I, 2, FALSE), "") | I5: Invoer:
I6: Criteria | K6: Input | N6: Service producten
B7: Datum: | C7: =TODAY() -> 46191 | I7: Land* (Export / Import) | K7: DE-Exp | N7: =Toeslagen!D1 -> Klep
B8: Laadmeters: | C8: =IF($K$11="", $J$11, $K$11) -> 2.5 | D8: LM | I8: Voer postcode* van het laad-/losadres in: | J8: =IF(K8="", "", TEXT(K8, "00")) -> 27 | K8: 27 | L8: =IF(K8="", "", IF(ISERROR(VLOOKUP(K8, INDIRECT("'" & K7 & "'!A:A"), 1, FALSE)), "Postcode niet gevonden", "")) | N8: =Toeslagen!F1 -> Kooiaap | O8: 0
B9: Gewicht: | C9: =IF($K$12="", $J$12, $K$12) -> 400 | D9: KG | I9: (Alleen eerste 2 karakters)
I10: Voer Laaddag in: | N10: =Toeslagen!H1 -> ADR
B11: Locatie laden | D11: Locatie lossen | G11: Transitdagen: | I11: Laadmeters* (verplichtveld) | J11: =L38 -> 2.38825 | K11: 2.5 | L11: =IFERROR(MAX(0, MIN(13.6, INDEX(INDIRECT("'" & K7 & "'!N:N"), MATCH(IF(K11 = "", J11, K11), INDIRECT("'" & K7 & "'!N:N"), 1) + (IF(K11 = "", J11, K11) > INDEX(INDIRECT("'" & K7 & "'!N:N"), MATCH(IF(K11 = "", J11, K11), INDIRECT("'" & K7 & "'!N:N"), 1)))))), "") -> 2.5 | M11: Afgerond naar eerst volgende (Laadmeters) | N11: =Toeslagen!J1 -> Documentatie
B12: =I18 -> Plaats: | C12: =IF(K18="","",K18) -> Leeuwarden | D12: =I22 -> Plaats: | F12: =IF(K22="","",K22) -> Schiffdorf-Sellstedt | I12: Gewicht* (verplichtveld) | J12: =K38 -> 3000 | K12: 400 | L12: =IFERROR(MAX(0,MIN(25000,INDEX(INDIRECT("'"&K7&"'!O:O"),MATCH(IF(K12="",J12,K12),INDIRECT("'"&K7&"'!O:O"),1)+(IF(K12="",J12,K12)>INDEX(INDIRECT("'"&K7&"'!O:O"),MATCH(IF(K12="",J12,K12),INDIRECT("'"&K7&"'!O:O"),1)))))), "") -> 700 | M12: Afgerond naar eerst volgende (Gewicht) | N12: =Toeslagen!K1 -> Inklaring
B13: =I19 -> Postcode: | C13: =IF(K19="","",K19) -> 8912 AS | D13: =I23 -> Postcode: | F13: =IF(K23="","",K23) -> 27619 | N13: =Toeslagen!L1 -> Uitvoering
B14: =I20 -> Land: | C14: =$K$20 -> NL | D14: =I24 -> Land: | F14: =$K$24 -> DE-Exp | I14: Dieseltoeslag* - maandnummer | J14: =MONTH(C7) -> 6 | K14: 0.24 | L14: Let op! Vul de juiste maand dieseltoeslag in | N14: =Toeslagen!M1 -> Handling
B15: Indicatie laaddag: | C15: =IF(K10=0, "Laaddag niet bekend", K10) -> Laaddag niet bekend | D15: Indicatie losdag: | F15: =IF(K10="Maandag", VLOOKUP(K8, INDIRECT("'" & K7 & "'!A:F"), 6, FALSE), IF(K10="Dinsdag", VLOOKUP(K8, INDIRECT("'" & K7 & "'!A:G"), 7, FALSE), IF(K10="Woensdag", VLOOKUP(K8, INDIRECT("'" & K7 & "'!A:H"), 8, FALSE), IF(K10="Donderdag", VLOOKUP(K8, INDIRECT("'" & K7 & "'!A:I"), 9, FALSE), IF(K10="Vrijdag", VLOOKUP(K8, INDIRECT("'" & K7 & "'!A:J"), 10, FALSE), "Losdag onbekend"))))) -> Losdag onbekend | G15: =IFERROR(VLOOKUP(K8, INDIRECT("'" & K7 & "'!A:E"), 4, FALSE), "") -> 2
B17: Transport tarief | D17: =IFERROR(MAX(INDEX(INDIRECT("'" & K7 & "'!P:EF"), MATCH(Invoer!L11, INDIRECT("'" & K7 & "'!N:N")), Invoer!U24), INDEX(INDIRECT("'" & K7 & "'!P:EF"), MATCH(Invoer!L12, INDIRECT("'" & K7 & "'!O:O"), 0), Invoer!U24)) + O18, "") -> 355.18172 | I17: Locatie laden:
B18: =I14 -> Dieseltoeslag* - maandnummer | C18: =J14 -> 6 | D18: =IFERROR((D17+D21+D22)*E18,"") -> 85.243614 | E18: =K14 -> 0.24 | I18: Plaats: | K18: Leeuwarden
I19: Postcode: | K19: 8912 AS
B20: Extra service | I20: Land: | K20: =IF(Invoer!K7="", "NL", IF(RIGHT(Invoer!K7,4)="-Exp", "NL", VLOOKUP(Invoer!K7, Toeslagen!A:A, 1, FALSE))) -> NL
B21: =N7 -> Klep | D21: =IFERROR(IF(OR(O7=0, VLOOKUP(K7,Toeslagen!A:C, 3, FALSE)=""), 0, MAX(50, MIN(150, SUM(VLOOKUP(K7,Toeslagen!A:C, 3, FALSE)*O7)*D17))), "") -> 0 | I21: Locatie lossen: | N21: Opmerking:
B22: =N8 -> Kooiaap | D22: =IFERROR(VLOOKUP(K7, Toeslagen!A:F, 6, FALSE)*O8, "") -> 0 | I22: Plaats: | K22: Schiffdorf-Sellstedt
B23: =N10 -> ADR | D23: =IFERROR(IF(O10=0, 0, MAX(50, MIN(150, SUM(VLOOKUP(K7, Toeslagen!A:H, 8, FALSE)*O10)*D17))),"") -> 0 | I23: Postcode: | K23: 27619
B24: =N11 -> Documentatie | D24: =IFERROR(VLOOKUP(K7, Toeslagen!A:J, 10, FALSE)*O11, "") -> 0 | I24: Land: | K24: =IF(Invoer!K7="", "NL", IF(RIGHT(Invoer!K7,4)="-Imp", "NL", VLOOKUP(Invoer!K7, Toeslagen!A:A, 1, FALSE))) -> DE-Exp | S24: Zone | T24: =IFERROR(VLOOKUP(K8, INDIRECT("'" & K7 & "'!A:B"), 2, FALSE), "") -> 27 | U24: =IF(ISERROR(MATCH(Invoer!T24, INDIRECT("'" & K7 & "'!P5:EF5"), 0)), "Zone niet gevonden", MATCH(Invoer!T24, INDIRECT("'" & K7 & "'!P5:EF5"), 0)) -> 27
B25: =N12 -> Inklaring | D25: =IFERROR(VLOOKUP(K7, Toeslagen!A:K, 11, FALSE)*O12, "") -> 0
B26: =N13 -> Uitvoering | D26: =IFERROR(VLOOKUP(K7, Toeslagen!A:L, 12, FALSE)*O13, "") -> 0
B27: =N14 -> Handling | D27: =IFERROR(VLOOKUP(K7, Toeslagen!A:M, 13, FALSE)*O14, "") -> 0 | I27: Laadmeter berekening
B28: =IF(P19=0, "", P19) | D28: =IFERROR(IF(OR(D17="", O19=""), "", +O19), "") | I28: Omschrijving | J28: Aantal | K28: Gewicht | L28: Laadmeters | M28: L | N28: B | O28: Btruck | P28: Hmax
B29: =IF(P20=0, "", P20) | D29: =IFERROR(IF(OR(D18="", O20=""), "",D17*O20), "") | I29: Europallets | L29: =SUM( (M29 * N29) / O29)*J29 -> 0 | M29: 1.2 | N29: 0.8 | O29: 2.4 | P29: 2.4
I30: Blokpallets | L30: =SUM( (M30 * N30) / O30)*J30 -> 0 | M30: 1.2 | N30: 1 | O30: 2.4 | P30: 2.4
B31: =N21 -> Opmerking: | C31: =IF(O21=0, "",O21) | I31: Afwijkende maten 1 | J31: 2 | K31: 1500 | L31: =SUM( (M31 * N31) / O31)*J31 -> 2.38825 | M31: 2.33 | N31: 1.23 | O31: 2.4 | P31: 2.4
I32: Afwijkende maten 2 | L32: =SUM( (M32 * N32) / O32)*J32 -> 0 | O32: 2.4 | P32: 2.4
B33: Totaal Transport Tarief (incl. dieseltoeslag) | D33: =SUM(D17:D31) -> 440.42534 | I33: Afwijkende maten 3 | L33: =SUM( (M33 * N33) / O33)*J33 -> 0 | O33: 2.4 | P33: 2.4
B34: * Dieseltoeslag wordt berekent over transporttarief, klep en kooiaap | I34: Afwijkende maten 4 | L34: =SUM( (M34 * N34) / O34)*J34 -> 0 | O34: 2.4 | P34: 2.4
I35: Afwijkende maten 5 | L35: =SUM( (M35 * N35) / O35)*J35 -> 0 | O35: 2.4 | P35: 2.4
B36: De bedragen zijn gebaseerd op de transport aanvraag, bedragen op factuur kunnen hiervan afwijken. | I36: Afwijkende maten 6 | L36: =SUM( (M36 * N36) / O36)*J36 -> 0 | O36: 2.4 | P36: 2.4
B37: De bovenstaande brandstoftoeslag is een voorcalculatie, het werkelijke percentage kan hiervan afwijken. | I37: Afwijkende maten 7 | L37: =SUM( (M37 * N37) / O37)*J37 -> 0 | O37: 2.4 | P37: 2.4
B38: De bovenstaande bedragen zijn exclusief BTW en overige bijkomende kosten (zoals wettelijke verhogingen bv: tol, ETS etc.) | I38: Totaal: | K38: =SUM(J29*K29,J30*K30,J31*K31,J32*K32,J33*K33,J34*K34,J35*K35,J36*K36,J37*K37) -> 3000 | L38: =SUM(L29:L37) -> 2.38825 | M38: =IF(SUM(L29:L37) > 13.6, "Laadmeters meer dan het maximum", "")
B39: Laad- en losadres dient bereikbaar te zijn middels een grote truck- en trailercombinatie (max 40000kg) | M39: =IF(SUM(J29*K29,J30*K30,J31*K31,J32*K32,J33*K33,J34*K34,J35*K35,J36*K36,J37*K37) > 24000, "Gewicht meer dan het maximum", "")
B40: Wachturen (€ 65,- p/u) worden toegepast na 1 uur bij het laden/lossen van 1 t/m 7 LM en na 2 uur bij 7,1 t/m 13,6 LM (FTL).
B41: Let op! Bij feestdagen zijn er afwijkende vertrek- en leverdagen.
B42: Let op! Bij FTL's (13,6 LM) kan mogelijk een seizoenstoeslag worden berekend.
B43: Aan deze tariefsberekening kunnen geen rechten worden ontleend.

Sheet Toeslagen
A1: Landcode | B1: Land | C1: Klep (calc) | D1: Klep | E1: Toelichting | F1: Kooiaap | H1: ADR | I1: Toelichting | J1: Documentatie | K1: Inklaring | L1: Uitvoering | M1: Handling
B2: Nederland | D2: -1 | E2: Geen klep toeslag | F2: 75 | H2: -0.9 | I2: Min. € 50,- / Max. € 150,-
B3: België | D3: 0 | E3: Geen klep toeslag | F3: 75 | H3: 0.1 | I3: Min. € 50,- / Max. € 150,-
B4: Luxemburg | D4: 0 | E4: Geen klep toeslag | F4: 75 | H4: 0.1 | I4: Min. € 50,- / Max. € 150,-
A5: DE-Exp | B5: Duitsland | D5: 0 | E5: Geen klep toeslag | F5: 150 | H5: 0.1 | I5: Min. € 50,- / Max. € 150,-
B6: Oostenrijk | C6: 0.01 | D6: 50 | E6: Min. € 50,- / Max. € 150,- | F6: 150 | H6: 0.1 | I6: Min. € 50,- / Max. € 150,- | Q6: 1
B7: Denemarken | C7: 1 | D7: 150 | E7: Vaste toeslag | F7: 175 | H7: 0.1 | I7: Min. € 50,- / Max. € 150,-
B8: Polen | C8: 0.1 | D8: 0.1 | E8: Min. € 50,- / Max. € 150,- | F8: 200 | H8: 0.1 | I8: Min. € 50,- / Max. € 150,-
B9: Frankrijk | D9: 0 | E9: Geen klep toeslag | F9: 150 | H9: 0.1 | I9: Min. € 50,- / Max. € 150,-
B10: Spanje | C10: 0.01 | D10: 50 | E10: Min. € 50,- / Max. € 150,- | F10: 300 | H10: 0.1 | I10: Min. € 50,- / Max. € 150,- | Q10: 1
B11: Portugal | C11: 0.1 | D11: 0.1 | E11: Min. € 50,- / Max. € 150,- | F11: 350 | H11: 0.1 | I11: Min. € 50,- / Max. € 150,-
B12: United Kingdom | C12: 0.1 | D12: 0.1 | E12: Min. € 50,- / Max. € 150,- | F12: 200 | H12: 0.1 | I12: Min. € 50,- / Max. € 150,- | K12: 75 | L12: 60 | M12: 50
B13: Ierland | E13: Op aanvraag | I13: Op aanvraag
B14: Italië | C14: 0.1 | D14: 0.1 | E14: Min. € 50,- / Max. € 150,- | F14: 0 | H14: 0.1 | I14: Min. € 50,- / Max. € 150,-
B15: Zwitserland | C15: 0.1 | D15: 0.1 | E15: Min. € 50,- / Max. € 150,- | F15: 0 | H15: 0.1 | I15: Min. € 50,- / Max. € 150,- | J15: 100
B16: Zweden | C16: 0.1 | D16: 0.1 | E16: Min. € 50,- / Max. € 150,- | F16: 200 | H16: 0.1 | I16: Min. € 50,- / Max. € 150,-
B17: Finland | C17: 0.1 | D17: 0.1 | E17: Min. € 50,- / Max. € 150,- | F17: 200 | H17: 0.1 | I17: Min. € 50,- / Max. € 150,-
B18: Noorwegen | C18: 0.1 | D18: 0.1 | E18: Min. € 50,- / Max. € 150,- | F18: 200 | H18: 0.1 | I18: Min. € 50,- / Max. € 150,- | J18: 100
B19: Polen | C19: 0.1 | D19: 0.1 | E19: Min. € 50,- / Max. € 150,- | F19: 200 | H19: 0.1 | I19: Min. € 50,- / Max. € 150,-
B20: Tsjechië | C20: 0.1 | D20: 0.1 | E20: Min. € 50,- / Max. € 150,- | F20: 200 | H20: 0.1 | I20: Min. € 50,- / Max. € 150,-
B21: Hongarije | C21: 0.1 | D21: 0.1 | E21: Min. € 50,- / Max. € 150,- | F21: 200 | H21: 0.1 | I21: Min. € 50,- / Max. € 150,-
B22: Slowakije | C22: 0.1 | D22: 0.1 | E22: Min. € 50,- / Max. € 150,- | F22: 200 | H22: 0.1 | I22: Min. € 50,- / Max. € 150,-
B23: Roemenië | C23: 0.1 | D23: 0.1 | E23: Min. € 50,- / Max. € 150,- | F23: 350 | H23: 0.1 | I23: Min. € 50,- / Max. € 150,-
B24: België | D24: 0 | E24: Geen klep toeslag | F24: 75 | H24: 0.1 | I24: Min. € 50,- / Max. € 150,-
B25: Luxemburg | D25: 0 | E25: Geen klep toeslag | F25: 75 | H25: 0.1 | I25: Min. € 50,- / Max. € 150,-
B26: Duitsland | D26: 0 | E26: Geen klep toeslag | F26: 150 | H26: 0.1 | I26: Min. € 50,- / Max. € 150,-
B27: Oostenrijk | C27: 0.01 | D27: 50 | E27: Min. € 50,- / Max. € 150,- | F27: 150 | H27: 0.1 | I27: Min. € 50,- / Max. € 150,-
B28: Denemarken | C28: 0.1 | D28: 150 | E28: Vaste toeslag | F28: 175 | H28: 0.1 | I28: Min. € 50,- / Max. € 150,-
B29: Polen | C29: 0.1 | D29: 0.1 | E29: Min. € 50,- / Max. € 150,- | F29: 200 | H29: 0.1 | I29: Min. € 50,- / Max. € 150,-
B30: Frankrijk | D30: 0 | E30: Geen klep toeslag | F30: 150 | H30: 0.1 | I30: Min. € 50,- / Max. € 150,-
B31: Spanje | C31: 0.01 | D31: 50 | E31: Min. € 50,- / Max. € 150,- | F31: 300 | H31: 0.1 | I31: Min. € 50,- / Max. € 150,-
B32: Portugal | C32: 0.1 | D32: 0.1 | E32: Min. € 50,- / Max. € 150,- | F32: 350 | H32: 0.1 | I32: Min. € 50,- / Max. € 150,-
B33: Italië | C33: 0.1 | D33: 0.1 | E33: Min. € 50,- / Max. € 150,- | F33: 0 | H33: 0.1 | I33: Min. € 50,- / Max. € 150,-
B34: United Kingdom | C34: 0.1 | D34: 0.1 | E34: Min. € 50,- / Max. € 150,- | F34: 200 | H34: 0.1 | I34: Min. € 50,- / Max. € 150,- | K34: 75 | L34: 60 | M34: 50
B35: NL Warehouse | D35: 0 | E35: Geen klep toeslag | F35: 75 | H35: 0.1 | I35: Min. € 50,- / Max. € 150,-
B36: BE Warehouse | D36: 0 | E36: Geen klep toeslag | F36: 75 | H36: 0.1 | I36: Min. € 50,- / Max. € 150,-
E43: Services
E44: 1
E45: 0

Sheet Dieseltoeslag
A1: Staffel dieseltoeslag vanaf 01.01.2026
A3: Brandstofprijs per liter excl. BTW
A5: Vanaf | B5: tot en met | C5: toeslag in %
A6: Per 01-01-26 | B6: 1.442 | C6: 0
A7: 1.443 | B7: 1.482 | C7: 1
A8: 1.483 | B8: 1.522 | C8: 2
A9: 1.523 | B9: 1.562 | C9: 3
A10: 1.563 | B10: 1.602 | C10: 4
A11: 1.603 | B11: 1.642 | C11: 5
A12: 1.643 | B12: 1.682 | C12: 6
A13: 1.683 | B13: 1.722 | C13: 7
A14: 1.723 | B14: 1.762 | C14: 8
A15: 1.763 | B15: 1.802 | C15: 9
A16: 1.803 | B16: 1.842 | C16: 10
A17: 1.843 | B17: 1.882 | C17: 11
A18: 1.883 | B18: 1.922 | C18: 12
... A23: 2.083 | B23: 2.122 | C23: 17
A25: De brandstoftoeslag wordt maandelijks bepaald
A26: Tarieven zijn te volgen via de website:
A27: www.oliecentrale.nl

Sheet BE-Exp
A5: Postcode | B5: Zone | C5: Afstand (km) | D5: Transitdagen | E5: Verste Locatie | F5: Laden Maandag = Lossen | G5: Laden Dinsdag = Lossen | H5: Laden Woensdag = Lossen | I5: Laden Donderdag = Lossen | J5: Laden Vrijdag = Lossen | N5: Laadmeters | O5: Gewicht | Y5: 10 | Z5: 11 | AA5: 12 | AB5: 13 | AC5: 14 | AD5: 15 | AE5: 16 | AF5: 17 | AG5: 18 | AH5: 19 | AI5: 20 | AJ5: 21 | AK5: 22 | AL5: 23 | AM5: 24 | AN5: 25 | AO5: 26 | AQ5: 28 | AR5: 29 | AS5: 30 | AT5: 31 | AU5: 32 | AV5: 33 | AW5: 34 | AX5: 35 | AY5: 36 | AZ5: 37 | BA5: 38 | BB5: 39 | BC5: 40 | BD5: 41 | BE5: 42 | BG5: 44 | BH5: 45 | BI5: 46 | BJ5: 47 | BK5: 48 | BL5: 49 | BM5: 50 | BN5: 51 | BO5: 52 | BP5: 53 | BR5: 55 | BS5: 56 | BW5: 60 | BX5: 61 | CA5: 64 | CB5: 65 | CC5: 66 | CD5: 67 | CE5: 68 | CF5: 69 | CG5: 70 | CH5: 71 | CJ5: 73 | CL5: 75 | CM5: 76 | CN5: 77 | CO5: 78 | CP5: 79 | CQ5: 80 | CS5: 82 | CT5: 83 | CU5: 84 | CV5: 85 | CW5: 86 | CX5: 87 | CY5: 88 | CZ5: 89 | DA5: 90 | DB5: 91 | DC5: 92 | DD5: 93 | DE5: 94 | DF5: 95 | DG5: 96 | DH5: 97 | DI5: 98 | DJ5: 99
A6: 1 | B6: 1 | C6: 700 | N6: 0 | O6: 0 | Y6: Bruxelles | Z6: Bruxelles | AA6: Bruxelles | AB6: Wavre | AC6: Nivelles | AD6: Halle | AE6: Sint-Pieters-Leeuw | AF6: Dilbeek | AG6: Vilvoorde | AH6: Zaventem | AI6: Antwerpen | AJ6: Antwerpen | AK6: Herentals | AL6: Turnhout | AM6: Mol | AN6: Lier | AO6: Antwerpen Berchem | AQ6: Mechelen | AR6: Schoten | AS6: Leuven | AT6: Boortmeerbeek | AU6: Aarschot | AV6: Tienen | AW6: Landen | AX6: Hasselt | AY6: Genk | AZ6: Tongeren | BA6: Sint-Truiden | BB6: Pelt | BC6: Liege | BD6: Seraing | BE6: Hannut | BF6: Waremme | BG6: Flemalle | BH6: Huy | BI6: Visé | BJ6: Eupen | BK6: Verviers | BL6: Spa | BM6: Namur | BN6: Namur | BO6: Namur | BP6: Andenne | BR6: Dinant | BS6: Philippeville | BW6: Charleroi | BX6: Courcelles | BY6: Chatelet | CA6: Chimay | CB6: Beaumont | CC6: Bastogne | CD6: Arlon | CE6: Libramont-Chevigny | CF6: Marche-en-Famenne | CG6: Mons | CH6: La Louviere | CJ6: Boussu | CL6: Tournai | CM6: Peruwelz | CN6: Mouscron | CO6: Ath | CP6: Leuze-en-Hainaut | CQ6: Brugge | CS6: Brugge | CT6: Knokke-Heist | CU6: Oostende | CV6: Kortrijk | CW6: Diksmuide | CX6: Tielt | CY6: Roeselare | CZ6: Ieper | DA6: Gent | DB6: Sint-Niklaas | DC6: Dendermonde | DD6: Aalst | DE6: Ninove | DF6: Geraardsbergen | DG6: Ronse | DH6: Oudenaarde | DI6: Deinze | DJ6: Eeklo
A7: 2 | B7: 2 | C7: 710 | N7: 0.4 | O7: 700 | Y7: ='BE-Exp (O)'!Y7*(1+Toeslagen!$Q$3) -> 139.5264 | Z7: ='BE-Exp (O)'!Z7*(1+Toeslagen!$Q$3) -> 139.5264 | AA7: ='BE-Exp (O)'!AA7*(1+Toeslagen!$Q$3) -> 139.5264 | AB7: ='BE-Exp (O)'!AB7*(1+Toeslagen!$Q$3) -> 156.832 | AC7: ='BE-Exp (O)'!AC7*(1+Toeslagen!$Q$3) -> 156.832 | AD7: ='BE-Exp (O)'!AD7*(1+Toeslagen!$Q$3) -> 139.5264 | AE7: ='BE-Exp (O)'!AE7*(1+Toeslagen!$Q$3) -> 139.5264 | AF7: ='BE-Exp (O)'!AF7*(1+Toeslagen!$Q$3) -> 139.5264 | ... DJ7: ='BE-Exp (O)'!DJ7*(1+Toeslagen!$Q$3) -> 139.5264
A8: 3 | B8: 3 | C8: 720 | N8: 0.5 | O8: 875 | Y8: ='BE-Exp (O)'!Y8*(1+Toeslagen!$Q$3) -> 151.424 | Z8: ='BE-Exp (O)'!Z8*(1+Toeslagen!$Q$3) -> 151.424 | AA8: ='BE-Exp (O)'!AA8*(1+Toeslagen!$Q$3) -> 151.424 | AB8: ='BE-Exp (O)'!AB8*(1+Toeslagen!$Q$3) -> 173.056 | AC8: ='BE-Exp (O)'!AC8*(1+Toeslagen!$Q$3) -> 173.056 | AD8: ='BE-Exp (O)'!AD8*(1+Toeslagen!$Q$3) -> 151.424 | AE8: ='BE-Exp (O)'!AE8*(1+Toeslagen!$Q$3) -> 151.424 | AF8: ='BE-Exp (O)'!AF8*(1+Toeslagen!$Q$3) -> 151.424 | ... DJ8: ='BE-Exp (O)'!DJ8*(1+Toeslagen!$Q$3) -> 151.424
A9: 4 | B9: 4 | C9: 730 | N9: 0.8 | O9: 1400 | Y9: ='BE-Exp (O)'!Y9*(1+Toeslagen!$Q$3) -> 178.464 | Z9: ='BE-Exp (O)'!Z9*(1+Toeslagen!$Q$3) -> 178.464 | AA9: ='BE-Exp (O)'!AA9*(1+Toeslagen!$Q$3) -> 178.464 | AB9: ='BE-Exp (O)'!AB9*(1+Toeslagen!$Q$3) -> 194.42842 | AC9: ='BE-Exp (O)'!AC9*(1+Toeslagen!$Q$3) -> 194.42842 | AD9: ='BE-Exp (O)'!AD9*(1+Toeslagen!$Q$3) -> 178.464 | AE9: ='BE-Exp (O)'!AE9*(1+Toeslagen!$Q$3) -> 178.464 | AF9: ='BE-Exp (O)'!AF9*(1+Toeslagen!$Q$3) -> 178.464 | ... DJ9: ='BE-Exp (O)'!DJ9*(1+Toeslagen!$Q$3) -> 178.464
A10: 6 | B10: 6 | C10: 630 | N10: 1 | O10: 1750 | Y10: ='BE-Exp (O)'!Y10*(1+Toeslagen!$Q$3) -> 183.872 | Z10: ='BE-Exp (O)'!Z10*(1+Toeslagen!$Q$3) -> 183.872 | AA10: ='BE-Exp (O)'!AA10*(1+Toeslagen!$Q$3) -> 183.872 | AB10: ='BE-Exp (O)'!AB10*(1+Toeslagen!$Q$3) -> 212.65608 | AC10: ='BE-Exp (O)'!AC10*(1+Toeslagen!$Q$3) -> 212.65608 | AD10: ='BE-Exp (O)'!AD10*(1+Toeslagen!$Q$3) -> 183.872 | AE10: ='BE-Exp (O)'!AE10*(1+Toeslagen!$Q$3) -> 183.872 | AF10: ='BE-Exp (O)'!AF10*(1+Toeslagen!$Q$3) -> 183.872 | ... DJ10: ='BE-Exp (O)'!DJ10*(1+Toeslagen!$Q$3) -> 183.872
A11: 7 | B11: 7 | C11: 700 | N11: 1.2 | O11: 2100 | Y11: ='BE-Exp (O)'!Y11*(1+Toeslagen!$Q$3) -> 192.5248 | Z11: ='BE-Exp (O)'!Z11*(1+Toeslagen!$Q$3) -> 192.5248 | AA11: ='BE-Exp (O)'!AA11*(1+Toeslagen!$Q$3) -> 192.5248 | AB11: ='BE-Exp (O)'!AB11*(1+Toeslagen!$Q$3) -> 228.09157 | AC11: ='BE-Exp (O)'!AC11*(1+Toeslagen!$Q$3) -> 228.09157 | AD11: ='BE-Exp (O)'!AD11*(1+Toeslagen!$Q$3) -> 192.5248 | AE11: ='BE-Exp (O)'!AE11*(1+Toeslagen!$Q$3) -> 192.5248 | AF11: ='BE-Exp (O)'!AF11*(1+Toeslagen!$Q$3) -> 192.5248 | ... DJ11: ='BE-Exp (O)'!DJ11*(1+Toeslagen!$Q$3) -> 192.5248
A12: 8 | B12: 8 | C12: 630 | N12: 1.5 | O12: 2625 | Y12: ='BE-Exp (O)'!Y12*(1+Toeslagen!$Q$3) -> 210.912 | Z12: ='BE-Exp (O)'!Z12*(1+Toeslagen!$Q$3) -> 210.912 | AA12: ='BE-Exp (O)'!AA12*(1+Toeslagen!$Q$3) -> 210.912 | AB12: ='BE-Exp (O)'!AB12*(1+Toeslagen!$Q$3) -> 245.63708 | AC12: ='BE-Exp (O)'!AC12*(1+Toeslagen!$Q$3) -> 245.63708 | AD12: ='BE-Exp (O)'!AD12*(1+Toeslagen!$Q$3) -> 210.912 | AE12: ='BE-Exp (O)'!AE12*(1+Toeslagen!$Q$3) -> 210.912 | AF12: ='BE-Exp (O)'!AF12*(1+Toeslagen!$Q$3) -> 210.912 | ... DJ12: ='BE-Exp (O)'!DJ12*(1+Toeslagen!$Q$3) -> 210.912
A13: 9 | B13: 9 | C13: 700 | N13: 1.6 | O13: 2800 | Y13: ='BE-Exp (O)'!Y13*(1+Toeslagen!$Q$3) -> 224.9728 | Z13: ='BE-Exp (O)'!Z13*(1+Toeslagen!$Q$3) -> 224.9728 | AA13: ='BE-Exp (O)'!AA13*(1+Toeslagen!$Q$3) -> 224.9728 | AB13: ='BE-Exp (O)'!AB13*(1+Toeslagen!$Q$3) -> 263.18258 | AC13: ='BE-Exp (O)'!AC13*(1+Toeslagen!$Q$3) -> 263.18258 | AD13: ='BE-Exp (O)'!AD13*(1+Toeslagen!$Q$3) -> 224.9728 | AE13: ='BE-Exp (O)'!AE13*(1+Toeslagen!$Q$3) -> 224.9728 | AF13: ='BE-Exp (O)'!AF13*(1+Toeslagen!$Q$3) -> 224.9728 | ... DJ13: ='BE-Exp (O)'!DJ13*(1+Toeslagen!$Q$3) -> 224.9728
A14: 10 | B14: 10 | C14: 470 | D14: 2 | F14: Woensdag | G14: Donderdag | H14: Vrijdag | I14: Maandag | J14: Dinsdag | N14: 2 | O14: 3500 | Y14: ='BE-Exp (O)'!Y14*(1+Toeslagen!$Q$3) -> 243.36 | Z14: ='BE-Exp (O)'!Z14*(1+Toeslagen!$Q$3) -> 243.36 | AA14: ='BE-Exp (O)'!AA14*(1+Toeslagen!$Q$3) -> 243.36 | AB14: ='BE-Exp (O)'!AB14*(1+Toeslagen!$Q$3) -> 280.72809 | AC14: ='BE-Exp (O)'!AC14*(1+Toeslagen!$Q$3) -> 280.72809 | AD14: ='BE-Exp (O)'!AD14*(1+Toeslagen!$Q$3) -> 243.36 | AE14: ='BE-Exp (O)'!AE14*(1+Toeslagen!$Q$3) -> 243.36 | AF14: ='BE-Exp (O)'!AF14*(1+Toeslagen!$Q$3) -> 243.36 | ... DJ14: ='BE-Exp (O)'!DJ14*(1+Toeslagen!$Q$3) -> 243.36
A15: 11 | B15: 11 | C15: 340 | D15: 2 | F15: Woensdag | G15: Donderdag | H15: Vrijdag | I15: Maandag | J15: Dinsdag | N15: 2.4 | O15: 4200 | Y15: ='BE-Exp (O)'!Y15*(1+Toeslagen!$Q$3) -> 268.66944 | Z15: ='BE-Exp (O)'!Z15*(1+Toeslagen!$Q$3) -> 268.66944 | AA15: ='BE-Exp (O)'!AA15*(1+Toeslagen!$Q$3) -> 268.66944 | AB15: ='BE-Exp (O)'!AB15*(1+Toeslagen!$Q$3) -> 298.27359 | AC15: ='BE-Exp (O)'!AC15*(1+Toeslagen!$Q$3) -> 298.27359 | AD15: ='BE-Exp (O)'!AD15*(1+Toeslagen!$Q$3) -> 268.66944 | AE15: ='BE-Exp (O)'!AE15*(1+Toeslagen!$Q$3) -> 268.66944 | AF15: ='BE-Exp (O)'!AF15*(1+Toeslagen!$Q$3) -> 268.66944 | ... DJ15: ='BE-Exp (O)'!DJ15*(1+Toeslagen!$Q$3) -> 268.66944
A16: 12 | B16: 12 | C16: 640 | D16: 2 | F16: Woensdag | G16: Donderdag | H16: Vrijdag | I16: Maandag | J16: Dinsdag | N16: 2.5 | O16: 4375 | Y16: ='BE-Exp (O)'!Y16*(1+Toeslagen!$Q$3) -> 273.86112 | Z16: ='BE-Exp (O)'!Z16*(1+Toeslagen!$Q$3) -> 273.86112 | AA16: ='BE-Exp (O)'!AA16*(1+Toeslagen!$Q$3) -> 273.86112 | AB16: ='BE-Exp (O)'!AB16*(1+Toeslagen!$Q$3) -> 315.8191 | AC16: ='BE-Exp (O)'!AC16*(1+Toeslagen!$Q$3) -> 315.8191 | AD16: ='BE-Exp (O)'!AD16*(1+Toeslagen!$Q$3) -> 273.86112 | AE16: ='BE-Exp (O)'!AE16*(1+Toeslagen!$Q$3) -> 273.86112 | AF16: ='BE-Exp (O)'!AF16*(1+Toeslagen!$Q$3) -> 273.86112 | ... DJ16: ='BE-Exp (O)'!DJ16*(1+Toeslagen!$Q$3) -> 273.86112
A17: 13 | B17: 13 | C17: 670 | D17: 2 | F17: Woensdag | G17: Donderdag | H17: Vrijdag | I17: Maandag | J17: Dinsdag | N17: 2.8 | O17: 4900 | Y17: ='BE-Exp (O)'!Y17*(1+Toeslagen!$Q$3) -> 290.73408 | Z17: ='BE-Exp (O)'!Z17*(1+Toeslagen!$Q$3) -> 290.73408 | AA17: ='BE-Exp (O)'!AA17*(1+Toeslagen!$Q$3) -> 290.73408 | AB17: ='BE-Exp (O)'!AB17*(1+Toeslagen!$Q$3) -> 333.3646 | AC17: ='BE-Exp (O)'!AC17*(1+Toeslagen!$Q$3) -> 333.3646 | AD17: ='BE-Exp (O)'!AD17*(1+Toeslagen!$Q$3) -> 290.73408 | AE17: ='BE-Exp (O)'!AE17*(1+Toeslagen!$Q$3) -> 290.73408 | AF17: ='BE-Exp (O)'!AF17*(1+Toeslagen!$Q$3) -> 290.73408 | ... DJ17: ='BE-Exp (O)'!DJ17*(1+Toeslagen!$Q$3) -> 290.73408
A18: 14 | B18: 14 | C18: 720 | D18: 2 | F18: Woensdag | G18: Donderdag | H18: Vrijdag | I18: Maandag | J18: Dinsdag | N18: 3 | O18: 5250 | Y18: ='BE-Exp (O)'!Y18*(1+Toeslagen!$Q$3) -> 303.71328 | Z18: ='BE-Exp (O)'!Z18*(1+Toeslagen!$Q$3) -> 303.71328 | AA18: ='BE-Exp (O)'!AA18*(1+Toeslagen!$Q$3) -> 303.71328 | AB18: ='BE-Exp (O)'!AB18*(1+Toeslagen!$Q$3) -> 350.91011 | AC18: ='BE-Exp (O)'!AC18*(1+Toeslagen!$Q$3) -> 350.91011 | AD18: ='BE-Exp (O)'!AD18*(1+Toeslagen!$Q$3) -> 303.71328 | AE18: ='BE-Exp (O)'!AE18*(1+Toeslagen!$Q$3) -> 303.71328 | AF18: ='BE-Exp (O)'!AF18*(1+Toeslagen!$Q$3) -> 303.71328 | ... DJ18: ='BE-Exp (O)'!DJ18*(1+Toeslagen!$Q$3) -> 303.71328
A19: 15 | B19: 15 | C19: 640 | D19: 2 | F19: Woensdag | G19: Donderdag | H19: Vrijdag | I19: Maandag | J19: Dinsdag | N19: 3.2 | O19: 5600 | Y19: ='BE-Exp (O)'!Y19*(1+Toeslagen!$Q$3) -> 315.39456 | Z19: ='BE-Exp (O)'!Z19*(1+Toeslagen!$Q$3) -> 315.39456 | AA19: ='BE-Exp (O)'!AA19*(1+Toeslagen!$Q$3) -> 315.39456 | AB19: ='BE-Exp (O)'!AB19*(1+Toeslagen!$Q$3) -> 368.45562 | AC19: ='BE-Exp (O)'!AC19*(1+Toeslagen!$Q$3) -> 368.45562 | AD19: ='BE-Exp (O)'!AD19*(1+Toeslagen!$Q$3) -> 315.39456 | AE19: ='BE-Exp (O)'!AE19*(1+Toeslagen!$Q$3) -> 315.39456 | AF19: ='BE-Exp (O)'!AF19*(1+Toeslagen!$Q$3) -> 315.39456 | ... DJ19: ='BE-Exp (O)'!DJ19*(1+Toeslagen!$Q$3) -> 315.39456
A20: 16 | B20: 16 | C20: 670 | D20: 2 | F20: Woensdag | G20: Donderdag | H20: Vrijdag | I20: Maandag | J20: Dinsdag | N20: 3.5 | O20: 6125 | Y20: ='BE-Exp (O)'!Y20*(1+Toeslagen!$Q$3) -> 332.26752 | Z20: ='BE-Exp (O)'!Z20*(1+Toeslagen!$Q$3) -> 332.26752 | AA20: ='BE-Exp (O)'!AA20*(1+Toeslagen!$Q$3) -> 332.26752 | AB20: ='BE-Exp (O)'!AB20*(1+Toeslagen!$Q$3) -> 386.00112 | AC20: ='BE-Exp (O)'!AC20*(1+Toeslagen!$Q$3) -> 386.00112 | AD20: ='BE-Exp (O)'!AD20*(1+Toeslagen!$Q$3) -> 332.26752 | AE20: ='BE-Exp (O)'!AE20*(1+Toeslagen!$Q$3) -> 332.26752 | AF20: ='BE-Exp (O)'!AF20*(1+Toeslagen!$Q$3) -> 332.26752 | ... DJ20: ='BE-Exp (O)'!DJ20*(1+Toeslagen!$Q$3) -> 332.26752
A21: 17 | B21: 17 | C21: 720 | D21: 2 | F21: Woensdag | G21: Donderdag | H21: Vrijdag | I21: Maandag | J21: Dinsdag | N21: 3.6 | O21: 6300 | Y21: ='BE-Exp (O)'!Y21*(1+Toeslagen!$Q$3) -> 338.75712 | Z21: ='BE-Exp (O)'!Z21*(1+Toeslagen!$Q$3) -> 338.75712 | AA21: ='BE-Exp (O)'!AA21*(1+Toeslagen!$Q$3) -> 338.75712 | AB21: ='BE-Exp (O)'!AB21*(1+Toeslagen!$Q$3) -> 403.54663 | AC21: ='BE-Exp (O)'!AC21*(1+Toeslagen!$Q$3) -> 403.54663 | AD21: ='BE-Exp (O)'!AD21*(1+Toeslagen!$Q$3) -> 338.75712 | AE21: ='BE-Exp (O)'!AE21*(1+Toeslagen!$Q$3) -> 338.75712 | AF21: ='BE-Exp (O)'!AF21*(1+Toeslagen!$Q$3) -> 338.75712 | ... DJ21: ='BE-Exp (O)'!DJ21*(1+Toeslagen!$Q$3) -> 338.75712
A22: 18 | B22: 18 | C22: 730 | D22: 2 | F22: Woensdag | G22: Donderdag | H22: Vrijdag | I22: Maandag | J22: Dinsdag | N22: 4 | O22: 7000 | Y22: ='BE-Exp (O)'!Y22*(1+Toeslagen!$Q$3) -> 363.4176 | Z22: ='BE-Exp (O)'!Z22*(1+Toeslagen!$Q$3) -> 363.4176 | AA22: ='BE-Exp (O)'!AA22*(1+Toeslagen!$Q$3) -> 363.4176 | AB22: ='BE-Exp (O)'!AB22*(1+Toeslagen!$Q$3) -> 421.09213 | AC22: ='BE-Exp (O)'!AC22*(1+Toeslagen!$Q$3) -> 421.09213 | AD22: ='BE-Exp (O)'!AD22*(1+Toeslagen!$Q$3) -> 363.4176 | AE22: ='BE-Exp (O)'!AE22*(1+Toeslagen!$Q$3) -> 363.4176 | AF22: ='BE-Exp (O)'!AF22*(1+Toeslagen!$Q$3) -> 363.4176 | ... DJ22: ='BE-Exp (O)'!DJ22*(1+Toeslagen!$Q$3) -> 363.4176
A23: 19 | B23: 19 | C23: 730 | D23: 2 | F23: Woensdag | G23: Donderdag | H23: Vrijdag | I23: Maandag | J23: Dinsdag | N23: 4.4 | O23: 7700 | Y23: ='BE-Exp (O)'!Y23*(1+Toeslagen!$Q$3) -> 385.48224 | Z23: ='BE-Exp (O)'!Z23*(1+Toeslagen!$Q$3) -> 385.48224 | AA23: ='BE-Exp (O)'!AA23*(1+Toeslagen!$Q$3) -> 385.48224 | AB23: ='BE-Exp (O)'!AB23*(1+Toeslagen!$Q$3) -> 438.63764 | AC23: ='BE-Exp (O)'!AC23*(1+Toeslagen!$Q$3) -> 438.63764 | AD23: ='BE-Exp (O)'!AD23*(1+Toeslagen!$Q$3) -> 385.48224 | AE23: ='BE-Exp (O)'!AE23*(1+Toeslagen!$Q$3) -> 385.48224 | AF23: ='BE-Exp (O)'!AF23*(1+Toeslagen!$Q$3) -> 385.48224 | ... DJ23: ='BE-Exp (O)'!DJ23*(1+Toeslagen!$Q$3) -> 385.48224
A24: 20 | B24: 20 | C24: 510 | D24: 2 | F24: Woensdag | G24: Donderdag | H24: Vrijdag | I24: Maandag | J24: Dinsdag | N24: 4.5 | O24: 7875 | Y24: ='BE-Exp (O)'!Y24*(1+Toeslagen!$Q$3) -> 390.67392 | Z24: ='BE-Exp (O)'!Z24*(1+Toeslagen!$Q$3) -> 390.67392 | AA24: ='BE-Exp (O)'!AA24*(1+Toeslagen!$Q$3) -> 390.67392 | AB24: ='BE-Exp (O)'!AB24*(1+Toeslagen!$Q$3) -> 456.18314 | AC24: ='BE-Exp (O)'!AC24*(1+Toeslagen!$Q$3) -> 456.18314 | AD24: ='BE-Exp (O)'!AD24*(1+Toeslagen!$Q$3) -> 390.67392 | AE24: ='BE-Exp (O)'!AE24*(1+Toeslagen!$Q$3) -> 390.67392 | AF24: ='BE-Exp (O)'!AF24*(1+Toeslagen!$Q$3) -> 390.67392 | ... DJ24: ='BE-Exp (O)'!DJ24*(1+Toeslagen!$Q$3) -> 390.67392
A25: 21 | B25: 21 | C25: 520 | D25: 2 | F25: Woensdag | G25: Donderdag | H25: Vrijdag | I25: Maandag | J25: Dinsdag | N25: 4.8 | O25: 8400 | Y25: ='BE-Exp (O)'!Y25*(1+Toeslagen!$Q$3) -> 406.24896 | Z25: ='BE-Exp (O)'!Z25*(1+Toeslagen!$Q$3) -> 406.24896 | AA25: ='BE-Exp (O)'!AA25*(1+Toeslagen!$Q$3) -> 406.24896 | AB25: ='BE-Exp (O)'!AB25*(1+Toeslagen!$Q$3) -> 473.72865 | AC25: ='BE-Exp (O)'!AC25*(1+Toeslagen!$Q$3) -> 473.72865 | AD25: ='BE-Exp (O)'!AD25*(1+Toeslagen!$Q$3) -> 406.24896 | AE25: ='BE-Exp (O)'!AE25*(1+Toeslagen!$Q$3) -> 406.24896 | AF25: ='BE-Exp (O)'!AF25*(1+Toeslagen!$Q$3) -> 406.24896 | ... DJ25: ='BE-Exp (O)'!DJ25*(1+Toeslagen!$Q$3) -> 406.24896
... A58: 55 | B58: 55 | C58: 410 | D58: 2 | F58: Woensdag | G58: Donderdag | H58: Vrijdag | I58: Maandag | J58: Dinsdag | N58: 13.6 | O58: 25000 | Y58: ='BE-Exp (O)'!Y58*(1+Toeslagen!$Q$3) -> 703.04 | Z58: ='BE-Exp (O)'!Z58*(1+Toeslagen!$Q$3) -> 703.04 | AA58: ='BE-Exp (O)'!AA58*(1+Toeslagen!$Q$3) -> 703.04 | AB58: ='BE-Exp (O)'!AB58*(1+Toeslagen!$Q$3) -> 751.712 | AC58: ='BE-Exp (O)'!AC58*(1+Toeslagen!$Q$3) -> 751.712 | AD58: ='BE-Exp (O)'!AD58*(1+Toeslagen!$Q$3) -> 703.04 | AE58: ='BE-Exp (O)'!AE58*(1+Toeslagen!$Q$3) -> 703.04 | AF58: ='BE-Exp (O)'!AF58*(1+Toeslagen!$Q$3) -> 703.04 | ... DJ58: ='BE-Exp (O)'!DJ58*(1+Toeslagen!$Q$3) -> 665.83296
A59: 56 | B59: 56 | C59: 420 | D59: 2 | F59: Woensdag | G59: Donderdag | H59: Vrijdag | I59: Maandag | J59: Dinsdag
A60: 57 | B60: 57 | C60: 250 | D60: 2 | F60: Woensdag | G60: Donderdag | H60: Vrijdag | I60: Maandag | J60: Dinsdag
A61: 58 | B61: 58 | C61: 200 | D61: 2 | F61: Woensdag | G61: Donderdag | H61: Vrijdag | I61: Maandag | J61: Dinsdag
A62: 59 | B62: 59 | C62: 230 | D62: 2 | F62: Woensdag | G62: Donderdag | H62: Vrijdag | I62: Maandag | J62: Dinsdag
A63: 60 | B63: 60 | C63: 430 | D63: 2 | F63: Woensdag | G63: Donderdag | H63: Vrijdag | I63: Maandag | J63: Dinsdag
A64: 61 | B64: 61 | C64: 450 | D64: 2 | F64: Woensdag | G64: Donderdag | H64: Vrijdag | I64: Maandag | J64: Dinsdag
A65: 63 | B65: 63 | C65: 530 | D65: 2 | F65: Woensdag | G65: Donderdag | H65: Vrijdag | I65: Maandag | J65: Dinsdag
A66: 64 | B66: 64 | C66: 440 | D66: 2 | F66: Woensdag | G66: Donderdag | H66: Vrijdag | I66: Maandag | J66: Dinsdag
A67: 65 | B67: 65 | C67: 530 | D67: 2 | F67: Woensdag | G67: Donderdag | H67: Vrijdag | I67: Maandag | J67: Dinsdag
A68: 66 | B68: 66 | C68: 600 | D68: 2 | F68: Woensdag | G68: Donderdag | H68: Vrijdag | I68: Maandag | J68: Dinsdag
A69: 67 | B69: 67 | C69: 530 | D69: 2 | F69: Woensdag | G69: Donderdag | H69: Vrijdag | I69: Maandag | J69: Dinsdag
A70: 68 | B70: 68 | C70: 640 | D70: 2 | F70: Woensdag | G70: Donderdag | H70: Vrijdag | I70: Maandag | J70: Dinsdag
... A100: 99 | B100: 99 | C100: 680 | D100: 2 | F100: Woensdag | G100: Donderdag | H100: Vrijdag | I100: Maandag | J100: Dinsdag

Sheet BE-Exp (O)
A5: Postcode | B5: Zone | C5: Afstand (km) | D5: Transitdagen | E5: Verste Locatie | F5: Laden Maandag = Lossen | G5: Laden Dinsdag = Lossen | H5: Laden Woensdag = Lossen | I5: Laden Donderdag = Lossen | J5: Laden Vrijdag = Lossen | N5: Laadmeters | O5: Gewicht | Y5: 10 | Z5: 11 | AA5: 12 | AB5: 13 | AC5: 14 | AD5: 15 | AE5: 16 | AF5: 17 | AG5: 18 | AH5: 19 | AI5: 20 | AJ5: 21 | AK5: 22 | AL5: 23 | AM5: 24 | AN5: 25 | AO5: 26 | AQ5: 28 | AR5: 29 | AS5: 30 | AT5: 31 | AU5: 32 | AV5: 33 | AW5: 34 | AX5: 35 | AY5: 36 | AZ5: 37 | BA5: 38 | BB5: 39 | BC5: 40 | BD5: 41 | BE5: 42 | BG5: 44 | BH5: 45 | BI5: 46 | BJ5: 47 | BK5: 48 | BL5: 49 | BM5: 50 | BN5: 51 | BO5: 52 | BP5: 53 | BR5: 55 | BS5: 56 | BW5: 60 | BX5: 61 | CA5: 64 | CB5: 65 | CC5: 66 | CD5: 67 | CE5: 68 | CF5: 69 | CG5: 70 | CH5: 71 | CJ5: 73 | CL5: 75 | CM5: 76 | CN5: 77 | CO5: 78 | CP5: 79 | CQ5: 80 | CS5: 82 | CT5: 83 | CU5: 84 | CV5: 85 | CW5: 86 | CX5: 87 | CY5: 88 | CZ5: 89 | DA5: 90 | DB5: 91 | DC5: 92 | DD5: 93 | DE5: 94 | DF5: 95 | DG5: 96 | DH5: 97 | DI5: 98 | DJ5: 99
A6: 1 | B6: 1 | C6: 700 | N6: 0 | O6: 0 | Y6: Bruxelles | Z6: Bruxelles | AA6: Bruxelles | AB6: Wavre | AC6: Nivelles | AD6: Halle | AE6: Sint-Pieters-Leeuw | AF6: Dilbeek | AG6: Vilvoorde | AH6: Zaventem | AI6: Antwerpen | AJ6: Antwerpen | AK6: Herentals | AL6: Turnhout | AM6: Mol | AN6: Lier | AO6: Antwerpen Berchem | AQ6: Mechelen | AR6: Schoten | AS6: Leuven | AT6: Boortmeerbeek | AU6: Aarschot | AV6: Tienen | AW6: Landen | AX6: Hasselt | AY6: Genk | AZ6: Tongeren | BA6: Sint-Truiden | BB6: Pelt | BC6: Liege | BD6: Seraing | BE6: Hannut | BF6: Waremme | BG6: Flemalle | BH6: Huy | BI6: Visé | BJ6: Eupen | BK6: Verviers | BL6: Spa | BM6: Namur | BN6: Namur | BO6: Namur | BP6: Andenne | BR6: Dinant | BS6: Philippeville | BW6: Charleroi | BX6: Courcelles | BY6: Chatelet | CA6: Chimay | CB6: Beaumont | CC6: Bastogne | CD6: Arlon | CE6: Libramont-Chevigny | CF6: Marche-en-Famenne | CG6: Mons | CH6: La Louviere | CJ6: Boussu | CL6: Tournai | CM6: Peruwelz | CN6: Mouscron | CO6: Ath | CP6: Leuze-en-Hainaut | CQ6: Brugge | CS6: Brugge | CT6: Knokke-Heist | CU6: Oostende | CV6: Kortrijk | CW6: Diksmuide | CX6: Tielt | CY6: Roeselare | CZ6: Ieper | DA6: Gent | DB6: Sint-Niklaas | DC6: Dendermonde | DD6: Aalst | DE6: Ninove | DF6: Geraardsbergen | DG6: Ronse | DH6: Oudenaarde | DI6: Deinze | DJ6: Eeklo
A7: 2 | B7: 2 | C7: 710 | N7: 0.4 | O7: 700 | Y7: 139.5264 | Z7: 139.5264 | AA7: 139.5264 | AB7: 156.832 | AC7: 156.832 | AD7: 139.5264 | AE7: 139.5264 | AF7: 139.5264 | AG7: 139.5264 | AH7: 139.5264 | AI7: 139.5264 | AJ7: 139.5264 | AK7: 139.5264 | AL7: 139.5264 | AM7: 139.5264 | AN7: 139.5264 | AO7: 139.5264 | AQ7: 139.5264 | AR7: 139.5264 | AS7: 139.5264 | AT7: 139.5264 | AU7: 139.5264 | AV7: 139.5264 | AW7: 139.5264 | AX7: 139.5264 | AY7: 139.5264 | AZ7: 139.5264 | BA7: 139.5264 | BB7: 139.5264 | BC7: 173.056 | BD7: 173.056 | BE7: 173.056 | BF7: 173.056 | BG7: 173.056 | BH7: 173.056 | BI7: 173.056 | BJ7: 173.056 | BK7: 173.056 | BL7: 173.056 | BM7: 173.056 | BN7: 173.056 | BO7: 173.056 | BP7: 173.056 | BR7: 173.056 | BS7: 173.056 | BW7: 173.056 | BX7: 173.056 | BY7: 173.056 | CA7: 173.056 | CB7: 173.056 | CC7: 189.28 | CD7: 189.28 | CE7: 189.28 | CF7: 189.28 | CG7: 173.056 | CH7: 173.056 | CJ7: 173.056 | CL7: 173.056 | CM7: 173.056 | CN7: 173.056 | CO7: 173.056 | CP7: 173.056 | CQ7: 169.8112 | CS7: 169.8112 | CT7: 169.8112 | CU7: 169.8112 | CV7: 169.8112 | CW7: 169.8112 | CX7: 169.8112 | CY7: 169.8112 | CZ7: 169.8112 | DA7: 139.5264 | DB7: 139.5264 | DC7: 139.5264 | DD7: 139.5264 | DE7: 139.5264 | DF7: 139.5264 | DG7: 139.5264 | DH7: 139.5264 | DI7: 139.5264 | DJ7: 139.5264
A8: 3 | B8: 3 | C8: 720 | N8: 0.5 | O8: 875 | Y8: 151.424 | Z8: 151.424 | AA8: 151.424 | AB8: 173.056 | AC8: 173.056 | AD8: 151.424 | AE8: 151.424 | AF8: 151.424 | AG8: 151.424 | AH8: 151.424 | AI8: 151.424 | AJ8: 151.424 | AK8: 151.424 | AL8: 151.424 | AM8: 151.424 | AN8: 151.424 | AO8: 151.424 | AQ8: 151.424 | AR8: 151.424 | AS8: 151.424 | AT8: 151.424 | AU8: 151.424 | AV8: 151.424 | AW8: 151.424 | AX8: 151.424 | AY8: 151.424 | AZ8: 151.424 | BA8: 151.424 | BB8: 151.424 | BC8: 188.35253 | BD8: 188.35253 | BE8: 188.35253 | BF8: 188.35253 | BG8: 188.35253 | BH8: 188.35253 | BI8: 188.35253 | BJ8: 188.35253 | BK8: 188.35253 | BL8: 188.35253 | BM8: 188.35253 | BN8: 188.35253 | BO8: 188.35253 | BP8: 188.35253 | BR8: 188.35253 | BS8: 188.35253 | BW8: 188.35253 | BX8: 188.35253 | BY8: 188.35253 | CA8: 188.35253 | CB8: 188.35253 | CC8: 216.9092 | CD8: 216.9092 | CE8: 216.9092 | CF8: 216.9092 | CG8: 188.35253 | CH8: 188.35253 | CJ8: 188.35253 | CL8: 188.35253 | CM8: 188.35253 | CN8: 188.35253 | CO8: 188.35253 | CP8: 188.35253 | CQ8: 177.3824 | CS8: 177.3824 | CT8: 177.3824 | CU8: 177.3824 | CV8: 177.3824 | CW8: 177.3824 | CX8: 177.3824 | CY8: 177.3824 | CZ8: 177.3824 | DA8: 151.424 | DB8: 151.424 | DC8: 151.424 | DD8: 151.424 | DE8: 151.424 | DF8: 151.424 | DG8: 151.424 | DH8: 151.424 | DI8: 151.424 | DJ8: 151.424
A9: 4 | B9: 4 | C9: 730 | N9: 0.8 | O9: 1400 | Y9: 178.464 | Z9: 178.464 | AA9: 178.464 | AB9: 194.42842 | AC9: 194.42842 | AD9: 178.464 | AE9: 178.464 | AF9: 178.464 | AG9: 178.464 | AH9: 178.464 | AI9: 178.464 | AJ9: 178.464 | AK9: 178.464 | AL9: 178.464 | AM9: 178.464 | AN9: 178.464 | AO9: 178.464 | AQ9: 178.464 | AR9: 178.464 | AS9: 178.464 | AT9: 178.464 | AU9: 178.464 | AV9: 178.464 | AW9: 178.464 | AX9: 178.464 | AY9: 178.464 | AZ9: 178.464 | BA9: 178.464 | BB9: 178.464 | BC9: 206.58019 | BD9: 206.58019 | BE9: 206.58019 | BF9: 206.58019 | BG9: 206.58019 | BH9: 206.58019 | BI9: 206.58019 | BJ9: 206.58019 | BK9: 206.58019 | BL9: 206.58019 | BM9: 206.58019 | BN9: 206.58019 | BO9: 206.58019 | BP9: 206.58019 | BR9: 206.58019 | BS9: 206.58019 | BW9: 206.58019 | BX9: 206.58019 | BY9: 206.58019 | CA9: 206.58019 | CB9: 206.58019 | CC9: 236.04825 | CD9: 236.04825 | CE9: 236.04825 | CF9: 236.04825 | CG9: 206.58019 | CH9: 206.58019 | CJ9: 206.58019 | CL9: 206.58019 | CM9: 206.58019 | CN9: 206.58019 | CO9: 206.58019 | CP9: 206.58019 | CQ9: 195.7696 | CS9: 195.7696 | CT9: 195.7696 | CU9: 195.7696 | CV9: 195.7696 | CW9: 195.7696 | CX9: 195.7696 | CY9: 195.7696 | CZ9: 195.7696 | DA9: 178.464 | DB9: 178.464 | DC9: 178.464 | DD9: 178.464 | DE9: 178.464 | DF9: 178.464 | DG9: 178.464 | DH9: 178.464 | DI9: 178.464 | DJ9: 178.464
A10: 6 | B10: 6 | C10: 630 | N10: 1 | O10: 1750 | Y10: 183.872 | Z10: 183.872 | AA10: 183.872 | AB10: 212.65608 | AC10: 212.65608 | AD10: 183.872 | AE10: 183.872 | AF10: 183.872 | AG10: 183.872 | AH10: 183.872 | AI10: 183.872 | AJ10: 183.872 | AK10: 183.872 | AL10: 183.872 | AM10: 183.872 | AN10: 183.872 | AO10: 183.872 | AQ10: 183.872 | AR10: 183.872 | AS10: 183.872 | AT10: 183.872 | AU10: 183.872 | AV10: 183.872 | AW10: 183.872 | AX10: 183.872 | AY10: 183.872 | AZ10: 183.872 | BA10: 183.872 | BB10: 183.872 | BC10: 224.80786 | BD10: 224.80786 | BE10: 224.80786 | BF10: 224.80786 | BG10: 224.80786 | BH10: 224.80786 | BI10: 224.80786 | BJ10: 224.80786 | BK10: 224.80786 | BL10: 224.80786 | BM10: 224.80786 | BN10: 224.80786 | BO10: 224.80786 | BP10: 224.80786 | BR10: 224.80786 | BS10: 224.80786 | BW10: 224.80786 | BX10: 224.80786 | BY10: 224.80786 | CA10: 224.80786 | CB10: 224.80786 | CC10: 248.80761 | CD10: 248.80761 | CE10: 248.80761 | CF10: 248.80761 | CG10: 224.80786 | CH10: 224.80786 | CJ10: 224.80786 | CL10: 224.80786 | CM10: 224.80786 | CN10: 224.80786 | CO10: 224.80786 | CP10: 224.80786 | CQ10: 205.504 | CS10: 205.504 | CT10: 205.504 | CU10: 205.504 | CV10: 205.504 | CW10: 205.504 | CX10: 205.504 | CY10: 205.504 | CZ10: 205.504 | DA10: 183.872 | DB10: 183.872 | DC10: 183.872 | DD10: 183.872 | DE10: 183.872 | DF10: 183.872 | DG10: 183.872 | DH10: 183.872 | DI10: 183.872 | DJ10: 183.872
A11: 7 | B11: 7 | C11: 700 | N11: 1.2 | O11: 2100 | Y11: 192.5248 | Z11: 192.5248 | AA11: 192.5248 | AB11: 228.09157 | AC11: 228.09157 | AD11: 192.5248 | AE11: 192.5248 | AF11: 192.5248 | AG11: 192.5248 | AH11: 192.5248 | AI11: 192.5248 | AJ11: 192.5248 | AK11: 192.5248 | AL11: 192.5248 | AM11: 192.5248 | AN11: 192.5248 | AO11: 192.5248 | AQ11: 192.5248 | AR11: 192.5248 | AS11: 192.5248 | AT11: 192.5248 | AU11: 192.5248 | AV11: 192.5248 | AW11: 192.5248 | AX11: 192.5248 | AY11: 192.5248 | AZ11: 192.5248 | BA11: 192.5248 | BB11: 192.5248 | BC11: 240.37343 | BD11: 240.37343 | BE11: 240.37343 | BF11: 240.37343 | BG11: 240.37343 | BH11: 240.37343 | BI11: 240.37343 | BJ11: 240.37343 | BK11: 240.37343 | BL11: 240.37343 | BM11: 240.37343 | BN11: 240.37343 | BO11: 240.37343 | BP11: 240.37343 | BR11: 240.37343 | BS11: 240.37343 | BW11: 240.37343 | BX11: 240.37343 | BY11: 240.37343 | CA11: 240.37343 | CB11: 240.37343 | CC11: 265.28804 | CD11: 265.28804 | CE11: 265.28804 | CF11: 265.28804 | CG11: 240.37343 | CH11: 240.37343 | CJ11: 240.37343 | CL11: 240.37343 | CM11: 240.37343 | CN11: 240.37343 | CO11: 240.37343 | CP11: 240.37343 | CQ11: 214.1568 | CS11: 214.1568 | CT11: 214.1568 | CU11: 214.1568 | CV11: 214.1568 | CW11: 214.1568 | CX11: 214.1568 | CY11: 214.1568 | CZ11: 214.1568 | DA11: 192.5248 | DB11: 192.5248 | DC11: 192.5248 | DD11: 192.5248 | DE11: 192.5248 | DF11: 192.5248 | DG11: 192.5248 | DH11: 192.5248 | DI11: 192.5248 | DJ11: 192.5248
A12: 8 | B12: 8 | C12: 630 | N12: 1.5 | O12: 2625 | Y12: 210.912 | Z12: 210.912 | AA12: 210.912 | AB12: 245.63708 | AC12: 245.63708 | AD12: 210.912 | AE12: 210.912 | AF12: 210.912 | AG12: 210.912 | AH12: 210.912 | AI12: 210.912 | AJ12: 210.912 | AK12: 210.912 | AL12: 210.912 | AM12: 210.912 | AN12: 210.912 | AO12: 210.912 | AQ12: 210.912 | AR12: 210.912 | AS12: 210.912 | AT12: 210.912 | AU12: 210.912 | AV12: 210.912 | AW12: 210.912 | AX12: 210.912 | AY12: 210.912 | AZ12: 210.912 | BA12: 210.912 | BB12: 210.912 | BC12: 259.67348 | BD12: 259.67348 | BE12: 259.67348 | BF12: 259.67348 | BG12: 259.67348 | BH12: 259.67348 | BI12: 259.67348 | BJ12: 259.67348 | BK12: 259.67348 | BL12: 259.67348 | BM12: 259.67348 | BN12: 259.67348 | BO12: 259.67348 | BP12: 259.67348 | BR12: 259.67348 | BS12: 259.67348 | BW12: 259.67348 | BX12: 259.67348 | BY12: 259.67348 | CA12: 259.67348 | CB12: 259.67348 | CC12: 287.39538 | CD12: 287.39538 | CE12: 287.39538 | CF12: 287.39538 | CG12: 259.67348 | CH12: 259.67348 | CJ12: 259.67348 | CL12: 259.67348 | CM12: 259.67348 | CN12: 259.67348 | CO12: 259.67348 | CP12: 259.67348 | CQ12: 232.544 | CS12: 232.544 | CT12: 232.544 | CU12: 232.544 | CV12: 232.544 | CW12: 232.544 | CX12: 232.544 | CY12: 232.544 | CZ12: 232.544 | DA12: 210.912 | DB12: 210.912 | DC12: 210.912 | DD12: 210.912 | DE12: 210.912 | DF12: 210.912 | DG12: 210.912 | DH12: 210.912 | DI12: 210.912 | DJ12: 210.912
A13: 9 | B13: 9 | C13: 700 | N13: 1.6 | O13: 2800 | Y13: 224.9728 | Z13: 224.9728 | AA13: 224.9728 | AB13: 263.18258 | AC13: 263.18258 | AD13: 224.9728 | AE13: 224.9728 | AF13: 224.9728 | AG13: 224.9728 | AH13: 224.9728 | AI13: 224.9728 | AJ13: 224.9728 | AK13: 224.9728 | AL13: 224.9728 | AM13: 224.9728 | AN13: 224.9728 | AO13: 224.9728 | AQ13: 224.9728 | AR13: 224.9728 | AS13: 224.9728 | AT13: 224.9728 | AU13: 224.9728 | AV13: 224.9728 | AW13: 224.9728 | AX13: 224.9728 | AY13: 224.9728 | AZ13: 224.9728 | BA13: 224.9728 | BB13: 224.9728 | BC13: 278.97354 | BD13: 278.97354 | BE13: 278.97354 | BF13: 278.97354 | BG13: 278.97354 | BH13: 278.97354 | BI13: 278.97354 | BJ13: 278.97354 | BK13: 278.97354 | BL13: 278.97354 | BM13: 278.97354 | BN13: 278.97354 | BO13: 278.97354 | BP13: 278.97354 | BR13: 278.97354 | BS13: 278.97354 | BW13: 278.97354 | BX13: 278.97354 | BY13: 278.97354 | CA13: 278.97354 | CB13: 278.97354 | CC13: 309.50272 | CD13: 309.50272 | CE13: 309.50272 | CF13: 309.50272 | CG13: 278.97354 | CH13: 278.97354 | CJ13: 278.97354 | CL13: 278.97354 | CM13: 278.97354 | CN13: 278.97354 | CO13: 278.97354 | CP13: 278.97354 | CQ13: 244.4416 | CS13: 244.4416 | CT13: 244.4416 | CU13: 244.4416 | CV13: 244.4416 | CW13: 244.4416 | CX13: 244.4416 | CY13: 244.4416 | CZ13: 244.4416 | DA13: 224.9728 | DB13: 224.9728 | DC13: 224.9728 | DD13: 224.9728 | DE13: 224.9728 | DF13: 224.9728 | DG13: 224.9728 | DH13: 224.9728 | DI13: 224.9728 | DJ13: 224.9728
A14: 10 | B14: 10 | C14: 470 | D14: 2 | F14: Woensdag | G14: Donderdag | H14: Vrijdag | I14: Maandag | J14: Dinsdag | N14: 2 | O14: 3500 | Y14: 243.36 | Z14: 243.36 | AA14: 243.36 | AB14: 280.72809 | AC14: 280.72809 | AD14: 243.36 | AE14: 243.36 | AF14: 243.36 | AG14: 243.36 | AH14: 243.36 | AI14: 243.36 | AJ14: 243.36 | AK14: 243.36 | AL14: 243.36 | AM14: 243.36 | AN14: 243.36 | AO14: 243.36 | AQ14: 243.36 | AR14: 243.36 | AS14: 243.36 | AT14: 243.36 | AU14: 243.36 | AV14: 243.36 | AW14: 243.36 | AX14: 243.36 | AY14: 243.36 | AZ14: 243.36 | BA14: 243.36 | BB14: 243.36 | BC14: 298.27359 | BD14: 298.27359 | BE14: 298.27359 | BF14: 298.27359 | BG14: 298.27359 | BH14: 298.27359 | BI14: 298.27359 | BJ14: 298.27359 | BK14: 298.27359 | BL14: 298.27359 | BM14: 298.27359 | BN14: 298.27359 | BO14: 298.27359 | BP14: 298.27359 | BR14: 298.27359 | BS14: 298.27359 | BW14: 298.27359 | BX14: 298.27359 | BY14: 298.27359 | CA14: 298.27359 | CB14: 298.27359 | CC14: 331.61005 | CD14: 331.61005 | CE14: 331.61005 | CF14: 331.61005 | CG14: 298.27359 | CH14: 298.27359 | CJ14: 298.27359 | CL14: 298.27359 | CM14: 298.27359 | CN14: 298.27359 | CO14: 298.27359 | CP14: 298.27359 | CQ14: 269.3184 | CS14: 269.3184 | CT14: 269.3184 | CU14: 269.3184 | CV14: 269.3184 | CW14: 269.3184 | CX14: 269.3184 | CY14: 269.3184 | CZ14: 269.3184 | DA14: 243.36 | DB14: 243.36 | DC14: 243.36 | DD14: 243.36 | DE14: 243.36 | DF14: 243.36 | DG14: 243.36 | DH14: 243.36 | DI14: 243.36 | DJ14: 243.36
A15: 11 | B15: 11 | C15: 340 | D15: 2 | F15: Woensdag | G15: Donderdag | H15: Vrijdag | I15: Maandag | J15: Dinsdag | N15: 2.4 | O15: 4200 | Y15: 268.66944 | Z15: 268.66944 | AA15: 268.66944 | AB15: 298.27359 | AC15: 298.27359 | AD15: 268.66944 | AE15: 268.66944 | AF15: 268.66944 | AG15: 268.66944 | AH15: 268.66944 | AI15: 268.66944 | AJ15: 268.66944 | AK15: 268.66944 | AL15: 268.66944 | AM15: 268.66944 | AN15: 268.66944 | AO15: 268.66944 | AQ15: 268.66944 | AR15: 268.66944 | AS15: 268.66944 | AT15: 268.66944 | AU15: 268.66944 | AV15: 268.66944 | AW15: 268.66944 | AX15: 268.66944 | AY15: 268.66944 | AZ15: 268.66944 | BA15: 268.66944 | BB15: 268.66944 | BC15: 317.57365 | BD15: 317.57365 | BE15: 317.57365 | BF15: 317.57365 | BG15: 317.57365 | BH15: 317.57365 | BI15: 317.57365 | BJ15: 317.57365 | BK15: 317.57365 | BL15: 317.57365 | BM15: 317.57365 | BN15: 317.57365 | BO15: 317.57365 | BP15: 317.57365 | BR15: 317.57365 | BS15: 317.57365 | BW15: 317.57365 | BX15: 317.57365 | BY15: 317.57365 | CA15: 317.57365 | CB15: 317.57365 | CC15: 353.71739 | CD15: 353.71739 | CE15: 353.71739 | CF15: 353.71739 | CG15: 317.57365 | CH15: 317.57365 | CJ15: 317.57365 | CL15: 317.57365 | CM15: 317.57365 | CN15: 317.57365 | CO15: 317.57365 | CP15: 317.57365 | CQ15: 286.624 | CS15: 286.624 | CT15: 286.624 | CU15: 286.624 | CV15: 286.624 | CW15: 286.624 | CX15: 286.624 | CY15: 286.624 | CZ15: 286.624 | DA15: 268.66944 | DB15: 268.66944 | DC15: 268.66944 | DD15: 268.66944 | DE15: 268.66944 | DF15: 268.66944 | DG15: 268.66944 | DH15: 268.66944 | DI15: 268.66944 | DJ15: 268.66944
A16: 12 | B16: 12 | C16: 640 | D16: 2 | F16: Woensdag | G16: Donderdag | H16: Vrijdag | I16: Maandag | J16: Dinsdag | N16: 2.5 | O16: 4375 | Y16: 273.86112 | Z16: 273.86112 | AA16: 273.86112 | AB16: 315.8191 | AC16: 315.8191 | AD16: 273.86112 | AE16: 273.86112 | AF16: 273.86112 | AG16: 273.86112 | AH16: 273.86112 | AI16: 273.86112 | AJ16: 273.86112 | AK16: 273.86112 | AL16: 273.86112 | AM16: 273.86112 | AN16: 273.86112 | AO16: 273.86112 | AQ16: 273.86112 | AR16: 273.86112 | AS16: 273.86112 | AT16: 273.86112 | AU16: 273.86112 | AV16: 273.86112 | AW16: 273.86112 | AX16: 273.86112 | AY16: 273.86112 | AZ16: 273.86112 | BA16: 273.86112 | BB16: 273.86112 | BC16: 336.87371 | BD16: 336.87371 | BE16: 336.87371 | BF16: 336.87371 | BG16: 336.87371 | BH16: 336.87371 | BI16: 336.87371 | BJ16: 336.87371 | BK16: 336.87371 | BL16: 336.87371 | BM16: 336.87371 | BN16: 336.87371 | BO16: 336.87371 | BP16: 336.87371 | BR16: 336.87371 | BS16: 336.87371 | BW16: 336.87371 | BX16: 336.87371 | BY16: 336.87371 | CA16: 336.87371 | CB16: 336.87371 | CC16: 375.82473 | CD16: 375.82473 | CE16: 375.82473 | CF16: 375.82473 | CG16: 336.87371 | CH16: 336.87371 | CJ16: 336.87371 | CL16: 336.87371 | CM16: 336.87371 | CN16: 336.87371 | CO16: 336.87371 | CP16: 336.87371 | CQ16: 305.0112 | CS16: 305.0112 | CT16: 305.0112 | CU16: 305.0112 | CV16: 305.0112 | CW16: 305.0112 | CX16: 305.0112 | CY16: 305.0112 | CZ16: 305.0112 | DA16: 273.86112 | DB16: 273.86112 | DC16: 273.86112 | DD16: 273.86112 | DE16: 273.86112 | DF16: 273.86112 | DG16: 273.86112 | DH16: 273.86112 | DI16: 273.86112 | DJ16: 273.86112
A17: 13 | B17: 13 | C17: 670 | D17: 2 | F17: Woensdag | G17: Donderdag | H17: Vrijdag | I17: Maandag | J17: Dinsdag | N17: 2.8 | O17: 4900 | Y17: 290.73408 | Z17: 290.73408 | AA17: 290.73408 | AB17: 333.3646 | AC17: 333.3646 | AD17: 290.73408 | AE17: 290.73408 | AF17: 290.73408 | AG17: 290.73408 | AH17: 290.73408 | AI17: 290.73408 | AJ17: 290.73408 | AK17: 290.73408 | AL17: 290.73408 | AM17: 290.73408 | AN17: 290.73408 | AO17: 290.73408 | AQ17: 290.73408 | AR17: 290.73408 | AS17: 290.73408 | AT17: 290.73408 | AU17: 290.73408 | AV17: 290.73408 | AW17: 290.73408 | AX17: 290.73408 | AY17: 290.73408 | AZ17: 290.73408 | BA17: 290.73408 | BB17: 290.73408 | BC17: 356.17376 | BD17: 356.17376 | BE17: 356.17376 | BF17: 356.17376 | BG17: 356.17376 | BH17: 356.17376 | BI17: 356.17376 | BJ17: 356.17376 | BK17: 356.17376 | BL17: 356.17376 | BM17: 356.17376 | BN17: 356.17376 | BO17: 356.17376 | BP17: 356.17376 | BR17: 356.17376 | BS17: 356.17376 | BW17: 356.17376 | BX17: 356.17376 | BY17: 356.17376 | CA17: 356.17376 | CB17: 356.17376 | CC17: 397.93206 | CD17: 397.93206 | CE17: 397.93206 | CF17: 397.93206 | CG17: 356.17376 | CH17: 356.17376 | CJ17: 356.17376 | CL17: 356.17376 | CM17: 356.17376 | CN17: 356.17376 | CO17: 356.17376 | CP17: 356.17376 | CQ17: 317.9904 | CS17: 317.9904 | CT17: 317.9904 | CU17: 317.9904 | CV17: 317.9904 | CW17: 317.9904 | CX17: 317.9904 | CY17: 317.9904 | CZ17: 317.9904 | DA17: 290.73408 | DB17: 290.73408 | DC17: 290.73408 | DD17: 290.73408 | DE17: 290.73408 | DF17: 290.73408 | DG17: 290.73408 | DH17: 290.73408 | DI17: 290.73408 | DJ17: 290.73408
A18: 14 | B18: 14 | C18: 720 | D18: 2 | F18: Woensdag | G18: Donderdag | H18: Vrijdag | I18: Maandag | J18: Dinsdag | N18: 3 | O18: 5250 | Y18: 303.71328 | Z18: 303.71328 | AA18: 303.71328 | AB18: 350.91011 | AC18: 350.91011 | AD18: 303.71328 | AE18: 303.71328 | AF18: 303.71328 | AG18: 303.71328 | AH18: 303.71328 | AI18: 303.71328 | AJ18: 303.71328 | AK18: 303.71328 | AL18: 303.71328 | AM18: 303.71328 | AN18: 303.71328 | AO18: 303.71328 | AQ18: 303.71328 | AR18: 303.71328 | AS18: 303.71328 | AT18: 303.71328 | AU18: 303.71328 | AV18: 303.71328 | AW18: 303.71328 | AX18: 303.71328 | AY18: 303.71328 | AZ18: 303.71328 | BA18: 303.71328 | BB18: 303.71328 | BC18: 375.47382 | BD18: 375.47382 | BE18: 375.47382 | BF18: 375.47382 | BG18: 375.47382 | BH18: 375.47382 | BI18: 375.47382 | BJ18: 375.47382 | BK18: 375.47382 | BL18: 375.47382 | BM18: 375.47382 | BN18: 375.47382 | BO18: 375.47382 | BP18: 375.47382 | BR18: 375.47382 | BS18: 375.47382 | BW18: 375.47382 | BX18: 375.47382 | BY18: 375.47382 | CA18: 375.47382 | CB18: 375.47382 | CC18: 420.0394 | CD18: 420.0394 | CE18: 420.0394 | CF18: 420.0394 | CG18: 375.47382 | CH18: 375.47382 | CJ18: 375.47382 | CL18: 375.47382 | CM18: 375.47382 | CN18: 375.47382 | CO18: 375.47382 | CP18: 375.47382 | CQ18: 336.3776 | CS18: 336.3776 | CT18: 336.3776 | CU18: 336.3776 | CV18: 336.3776 | CW18: 336.3776 | CX18: 336.3776 | CY18: 336.3776 | CZ18: 336.3776 | DA18: 303.71328 | DB18: 303.71328 | DC18: 303.71328 | DD18: 303.71328 | DE18: 303.71328 | DF18: 303.71328 | DG18: 303.71328 | DH18: 303.71328 | DI18: 303.71328 | DJ18: 303.71328
A19: 15 | B19: 15 | C19: 640 | D19: 2 | F19: Woensdag | G19: Donderdag | H19: Vrijdag | I19: Maandag | J19: Dinsdag | N19: 3.2 | O19: 5600 | Y19: 315.39456 | Z19: 315.39456 | AA19: 315.39456 | AB19: 368.45562 | AC19: 368.45562 | AD19: 315.39456 | AE19: 315.39456 | AF19: 315.39456 | AG19: 315.39456 | AH19: 315.39456 | AI19: 315.39456 | AJ19: 315.39456 | AK19: 315.39456 | AL19: 315.39456 | AM19: 315.39456 | AN19: 315.39456 | AO19: 315.39456 | AQ19: 315.39456 | AR19: 315.39456 | AS19: 315.39456 | AT19: 315.39456 | AU19: 315.39456 | AV19: 315.39456 | AW19: 315.39456 | AX19: 315.39456 | AY19: 315.39456 | AZ19: 315.39456 | BA19: 315.39456 | BB19: 315.39456 | BC19: 394.77387 | BD19: 394.77387 | BE19: 394.77387 | BF19: 394.77387 | BG19: 394.77387 | BH19: 394.77387 | BI19: 394.77387 | BJ19: 394.77387 | BK19: 394.77387 | BL19: 394.77387 | BM19: 394.77387 | BN19: 394.77387 | BO19: 394.77387 | BP19: 394.77387 | BR19: 394.77387 | BS19: 394.77387 | BW19: 394.77387 | BX19: 394.77387 | BY19: 394.77387 | CA19: 394.77387 | CB19: 394.77387 | CC19: 442.14674 | CD19: 442.14674 | CE19: 442.14674 | CF19: 442.14674 | CG19: 394.77387 | CH19: 394.77387 | CJ19: 394.77387 | CL19: 394.77387 | CM19: 394.77387 | CN19: 394.77387 | CO19: 394.77387 | CP19: 394.77387 | CQ19: 348.2752 | CS19: 348.2752 | CT19: 348.2752 | CU19: 348.2752 | CV19: 348.2752 | CW19: 348.2752 | CX19: 348.2752 | CY19: 348.2752 | CZ19: 348.2752 | DA19: 315.39456 | DB19: 315.39456 | DC19: 315.39456 | DD19: 315.39456 | DE19: 315.39456 | DF19: 315.39456 | DG19: 315.39456 | DH19: 315.39456 | DI19: 315.39456 | DJ19: 315.39456
A20: 16 | B20: 16 | C20: 670 | D20: 2 | F20: Woensdag | G20: Donderdag | H20: Vrijdag | I20: Maandag | J20: Dinsdag | N20: 3.5 | O20: 6125 | Y20: 332.26752 | Z20: 332.26752 | AA20: 332.26752 | AB20: 386.00112 | AC20: 386.00112 | AD20: 332.26752 | AE20: 332.26752 | AF20: 332.26752 | AG20: 332.26752 | AH20: 332.26752 | AI20: 332.26752 | AJ20: 332.26752 | AK20: 332.26752 | AL20: 332.26752 | AM20: 332.26752 | AN20: 332.26752 | AO20: 332.26752 | AQ20: 332.26752 | AR20: 332.26752 | AS20: 332.26752 | AT20: 332.26752 | AU20: 332.26752 | AV20: 332.26752 | AW20: 332.26752 | AX20: 332.26752 | AY20: 332.26752 | AZ20: 332.26752 | BA20: 332.26752 | BB20: 332.26752 | BC20: 414.07393 | BD20: 414.07393 | BE20: 414.07393 | BF20: 414.07393 | BG20: 414.07393 | BH20: 414.07393 | BI20: 414.07393 | BJ20: 414.07393 | BK20: 414.07393 | BL20: 414.07393 | BM20: 414.07393 | BN20: 414.07393 | BO20: 414.07393 | BP20: 414.07393 | BR20: 414.07393 | BS20: 414.07393 | BW20: 414.07393 | BX20: 414.07393 | BY20: 414.07393 | CA20: 414.07393 | CB20: 414.07393 | CC20: 464.25408 | CD20: 464.25408 | CE20: 464.25408 | CF20: 464.25408 | CG20: 414.07393 | CH20: 414.07393 | CJ20: 414.07393 | CL20: 414.07393 | CM20: 414.07393 | CN20: 414.07393 | CO20: 414.07393 | CP20: 414.07393 | CQ20: 366.6624 | CS20: 366.6624 | CT20: 366.6624 | CU20: 366.6624 | CV20: 366.6624 | CW20: 366.6624 | CX20: 366.6624 | CY20: 366.6624 | CZ20: 366.6624 | DA20: 332.26752 | DB20: 332.26752 | DC20: 332.26752 | DD20: 332.26752 | DE20: 332.26752 | DF20: 332.26752 | DG20: 332.26752 | DH20: 332.26752 | DI20: 332.26752 | DJ20: 332.26752
A21: 17 | B21: 17 | C21: 720 | D21: 2 | F21: Woensdag | G21: Donderdag | H21: Vrijdag | I21: Maandag | J21: Dinsdag | N21: 3.6 | O21: 6300 | Y21: 338.75712 | Z21: 338.75712 | AA21: 338.75712 | AB21: 403.54663 | AC21: 403.54663 | AD21: 338.75712 | AE21: 338.75712 | AF21: 338.75712 | AG21: 338.75712 | AH21: 338.75712 | AI21: 338.75712 | AJ21: 338.75712 | AK21: 338.75712 | AL21: 338.75712 | AM21: 338.75712 | AN21: 338.75712 | AO21: 338.75712 | AQ21: 338.75712 | AR21: 338.75712 | AS21: 338.75712 | AT21: 338.75712 | AU21: 338.75712 | AV21: 338.75712 | AW21: 338.75712 | AX21: 338.75712 | AY21: 338.75712 | AZ21: 338.75712 | BA21: 338.75712 | BB21: 338.75712 | BC21: 433.37399 | BD21: 433.37399 | BE21: 433.37399 | BF21: 433.37399 | BG21: 433.37399 | BH21: 433.37399 | BI21: 433.37399 | BJ21: 433.37399 | BK21: 433.37399 | BL21: 433.37399 | BM21: 433.37399 | BN21: 433.37399 | BO21: 433.37399 | BP21: 433.37399 | BR21: 433.37399 | BS21: 433.37399 | BW21: 433.37399 | BX21: 433.37399 | BY21: 433.37399 | CA21: 433.37399 | CB21: 433.37399 | CC21: 486.36141 | CD21: 486.36141 | CE21: 486.36141 | CF21: 486.36141 | CG21: 433.37399 | CH21: 433.37399 | CJ21: 433.37399 | CL21: 433.37399 | CM21: 433.37399 | CN21: 433.37399 | CO21: 433.37399 | CP21: 433.37399 | CQ21: 385.0496 | CS21: 385.0496 | CT21: 385.0496 | CU21: 385.0496 | CV21: 385.0496 | CW21: 385.0496 | CX21: 385.0496 | CY21: 385.0496 | CZ21: 385.0496 | DA21: 338.75712 | DB21: 338.75712 | DC21: 338.75712 | DD21: 338.75712 | DE21: 338.75712 | DF21: 338.75712 | DG21: 338.75712 | DH21: 338.75712 | DI21: 338.75712 | DJ21: 338.75712
A22: 18 | B22: 18 | C22: 730 | D22: 2 | F22: Woensdag | G22: Donderdag | H22: Vrijdag | I22: Maandag | J22: Dinsdag | N22: 4 | O22: 7000 | Y22: 363.4176 | Z22: 363.4176 | AA22: 363.4176 | AB22: 421.09213 | AC22: 421.09213 | AD22: 363.4176 | AE22: 363.4176 | AF22: 363.4176 | AG22: 363.4176 | AH22: 363.4176 | AI22: 363.4176 | AJ22: 363.4176 | AK22: 363.4176 | AL22: 363.4176 | AM22: 363.4176 | AN22: 363.4176 | AO22: 363.4176 | AQ22: 363.4176 | AR22: 363.4176 | AS22: 363.4176 | AT22: 363.4176 | AU22: 363.4176 | AV22: 363.4176 | AW22: 363.4176 | AX22: 363.4176 | AY22: 363.4176 | AZ22: 363.4176 | BA22: 363.4176 | BB22: 363.4176 | BC22: 452.67404 | BD22: 452.67404 | BE22: 452.67404 | BF22: 452.67404 | BG22: 452.67404 | BH22: 452.67404 | BI22: 452.67404 | BJ22: 452.67404 | BK22: 452.67404 | BL22: 452.67404 | BM22: 452.67404 | BN22: 452.67404 | BO22: 452.67404 | BP22: 452.67404 | BR22: 452.67404 | BS22: 452.67404 | BW22: 452.67404 | BX22: 452.67404 | BY22: 452.67404 | CA22: 452.67404 | CB22: 452.67404 | CC22: 508.46875 | CD22: 508.46875 | CE22: 508.46875 | CF22: 508.46875 | CG22: 452.67404 | CH22: 452.67404 | CJ22: 452.67404 | CL22: 452.67404 | CM22: 452.67404 | CN22: 452.67404 | CO22: 452.67404 | CP22: 452.67404 | CQ22: 403.4368 | CS22: 403.4368 | CT22: 403.4368 | CU22: 403.4368 | CV22: 403.4368 | CW22: 403.4368 | CX22: 403.4368 | CY22: 403.4368 | CZ22: 403.4368 | DA22: 363.4176 | DB22: 363.4176 | DC22: 363.4176 | DD22: 363.4176 | DE22: 363.4176 | DF22: 363.4176 | DG22: 363.4176 | DH22: 363.4176 | DI22: 363.4176 | DJ22: 363.4176
A23: 19 | B23: 19 | C23: 730 | D23: 2 | F23: Woensdag | G23: Donderdag | H23: Vrijdag | I23: Maandag | J23: Dinsdag | N23: 4.4 | O23: 7700 | Y23: 385.48224 | Z23: 385.48224 | AA23: 385.48224 | AB23: 438.63764 | AC23: 438.63764 | AD23: 385.48224 | AE23: 385.48224 | AF23: 385.48224 | AG23: 385.48224 | AH23: 385.48224 | AI23: 385.48224 | AJ23: 385.48224 | AK23: 385.48224 | AL23: 385.48224 | AM23: 385.48224 | AN23: 385.48224 | AO23: 385.48224 | AQ23: 385.48224 | AR23: 385.48224 | AS23: 385.48224 | AT23: 385.48224 | AU23: 385.48224 | AV23: 385.48224 | AW23: 385.48224 | AX23: 385.48224 | AY23: 385.48224 | AZ23: 385.48224 | BA23: 385.48224 | BB23: 385.48224 | BC23: 471.9741 | BD23: 471.9741 | BE23: 471.9741 | BF23: 471.9741 | BG23: 471.9741 | BH23: 471.9741 | BI23: 471.9741 | BJ23: 471.9741 | BK23: 471.9741 | BL23: 471.9741 | BM23: 471.9741 | BN23: 471.9741 | BO23: 471.9741 | BP23: 471.9741 | BR23: 471.9741 | BS23: 471.9741 | BW23: 471.9741 | BX23: 471.9741 | BY23: 471.9741 | CA23: 471.9741 | CB23: 471.9741 | CC23: 530.57609 | CD23: 530.57609 | CE23: 530.57609 | CF23: 530.57609 | CG23: 471.9741 | CH23: 471.9741 | CJ23: 471.9741 | CL23: 471.9741 | CM23: 471.9741 | CN23: 471.9741 | CO23: 471.9741 | CP23: 471.9741 | CQ23: 427.232 | CS23: 427.232 | CT23: 427.232 | CU23: 427.232 | CV23: 427.232 | CW23: 427.232 | CX23: 427.232 | CY23: 427.232 | CZ23: 427.232 | DA23: 385.48224 | DB23: 385.48224 | DC23: 385.48224 | DD23: 385.48224 | DE23: 385.48224 | DF23: 385.48224 | DG23: 385.48224 | DH23: 385.48224 | DI23: 385.48224 | DJ23: 385.48224
A24: 20 | B24: 20 | C24: 510 | D24: 2 | F24: Woensdag | G24: Donderdag | H24: Vrijdag | I24: Maandag | J24: Dinsdag | N24: 4.5 | O24: 7875 | Y24: 390.67392 | Z24: 390.67392 | AA24: 390.67392 | AB24: 456.18314 | AC24: 456.18314 | AD24: 390.67392 | AE24: 390.67392 | AF24: 390.67392 | AG24: 390.67392 | AH24: 390.67392 | AI24: 390.67392 | AJ24: 390.67392 | AK24: 390.67392 | AL24: 390.67392 | AM24: 390.67392 | AN24: 390.67392 | AO24: 390.67392 | AQ24: 390.67392 | AR24: 390.67392 | AS24: 390.67392 | AT24: 390.67392 | AU24: 390.67392 | AV24: 390.67392 | AW24: 390.67392 | AX24: 390.67392 | AY24: 390.67392 | AZ24: 390.67392 | BA24: 390.67392 | BB24: 390.67392 | BC24: 491.27415 | BD24: 491.27415 | BE24: 491.27415 | BF24: 491.27415 | BG24: 491.27415 | BH24: 491.27415 | BI24: 491.27415 | BJ24: 491.27415 | BK24: 491.27415 | BL24: 491.27415 | BM24: 491.27415 | BN24: 491.27415 | BO24: 491.27415 | BP24: 491.27415 | BR24: 491.27415 | BS24: 491.27415 | BW24: 491.27415 | BX24: 491.27415 | BY24: 491.27415 | CA24: 491.27415 | CB24: 491.27415 | CC24: 552.68342 | CD24: 552.68342 | CE24: 552.68342 | CF24: 552.68342 | CG24: 491.27415 | CH24: 491.27415 | CJ24: 491.27415 | CL24: 491.27415 | CM24: 491.27415 | CN24: 491.27415 | CO24: 491.27415 | CP24: 491.27415 | CQ24: 443.456 | CS24: 443.456 | CT24: 443.456 | CU24: 443.456 | CV24: 443.456 | CW24: 443.456 | CX24: 443.456 | CY24: 443.456 | CZ24: 443.456 | DA24: 390.67392 | DB24: 390.67392 | DC24: 390.67392 | DD24: 390.67392 | DE24: 390.67392 | DF24: 390.67392 | DG24: 390.67392 | DH24: 390.67392 | DI24: 390.67392 | DJ24: 390.67392
A25: 21 | B25: 21 | C25: 520 | D25: 2 | F25: Woensdag | G25: Donderdag | H25: Vrijdag | I25: Maandag | J25: Dinsdag | N25: 4.8 | O25: 8400 | Y25: 406.24896 | Z25: 406.24896 | AA25: 406.24896 | AB25: 473.72865 | AC25: 473.72865 | AD25: 406.24896 | AE25: 406.24896 | AF25: 406.24896 | AG25: 406.24896 | AH25: 406.24896 | AI25: 406.24896 | AJ25: 406.24896 | AK25: 406.24896 | AL25: 406.24896 | AM25: 406.24896 | AN25: 406.24896 | AO25: 406.24896 | AQ25: 406.24896 | AR25: 406.24896 | AS25: 406.24896 | AT25: 406.24896 | AU25: 406.24896 | AV25: 406.24896 | AW25: 406.24896 | AX25: 406.24896 | AY25: 406.24896 | AZ25: 406.24896 | BA25: 406.24896 | BB25: 406.24896 | BC25: 510.57421 | BD25: 510.57421 | BE25: 510.57421 | BF25: 510.57421 | BG25: 510.57421 | BH25: 510.57421 | BI25: 510.57421 | BJ25: 510.57421 | BK25: 510.57421 | BL25: 510.57421 | BM25: 510.57421 | BN25: 510.57421 | BO25: 510.57421 | BP25: 510.57421 | BR25: 510.57421 | BS25: 510.57421 | BW25: 510.57421 | BX25: 510.57421 | BY25: 510.57421 | CA25: 510.57421 | CB25: 510.57421 | CC25: 574.79076 | CD25: 574.79076 | CE25: 574.79076 | CF25: 574.79076 | CG25: 510.57421 | CH25: 510.57421 | CJ25: 510.57421 | CL25: 510.57421 | CM25: 510.57421 | CN25: 510.57421 | CO25: 510.57421 | CP25: 510.57421 | CQ25: 452.1088 | CS25: 452.1088 | CT25: 452.1088 | CU25: 452.1088 | CV25: 452.1088 | CW25: 452.1088 | CX25: 452.1088 | CY25: 452.1088 | CZ25: 452.1088 | DA25: 406.24896 | DB25: 406.24896 | DC25: 406.24896 | DD25: 406.24896 | DE25: 406.24896 | DF25: 406.24896 | DG25: 406.24896 | DH25: 406.24896 | DI25: 406.24896 | DJ25: 406.24896
