Workbook
Name Laadmeters: #REF!
Name Postcode: #REF!
Name Tarieven: #REF!

Sheet Voorblad
A3: Offerte
A5: Team Freight Forwarding Logistics | E5: XPO Logistics Netherlands B.V.
A6: Marconiweg 14 | E6: Lagelandseweg 70
A7: 8501 XM Joure | E7: 6545 CG Nijmegen (NL)
A8: operations@tfflogistics.com | E8: Tel: +31 (0)24-372 4680
E9: sales.nl@xpo.com
A13: Laadadres (tenzij anders vermeld) | E13: Losadres (tenzij anders vermeld)
A14: NL (ex Waddeneilanden) | E14: te bevestigen op order
A17: Tarieven zijn geldig t/m 30-06-2026
A18: Tarieven zijn enkel geldig na schriftelijk akkoord binnen 14 dagen na dagtekening van toesturen van offertes.
A19: Voor onze algemene voorwaarden en toeslagen en condities verwijzen wij u naar de overige tabbladen.
A21: Akkoord voor tarieven en Algemene voorwaarden en condities:
A23: Handtekening | C23: =A5 -> Team Freight Forwarding Logistics

Sheet AT
A3: =Voorblad!A5 -> Team Freight Forwarding Logistics
A4: Export Oostenrijk
A6: kg | B6: ldm | C6: euplt | D6: blkplt | E6: 10 | F6: 11 | G6: 12 | H6: 13 | I6: 20 | J6: 21 | K6: 22 | L6: 23 | M6: 24 | N6: 25 | O6: 26 | P6: 27 | Q6: 28 | R6: 30 | S6: 31 | T6: 32 | U6: 33 | V6: 34 | W6: 35 | X6: 36 | Y6: 37 | Z6: 38 | AA6: 39 | AB6: 40 | AC6: 41 | AD6: 42 | AE6: 43 | AF6: 44 | AG6: 45 | AH6: 46 | AI6: 47 | AJ6: 48 | AK6: 49 | AL6: 50 | AM6: 51 | AN6: 52 | AO6: 53 | AP6: 54 | AQ6: 55 | AR6: 56 | AS6: 57 | AT6: 60 | AU6: 61 | AV6: 62 | AW6: 63 | AX6: 64 | AY6: 65 | AZ6: 66 | BA6: 67 | BB6: 68 | BC6: 69 | BD6: 70 | BE6: 71 | BF6: 72 | BG6: 73 | BH6: 74 | BI6: 75 | BJ6: 80 | BK6: 81 | BL6: 82 | BM6: 83 | BN6: 84 | BO6: 85 | BP6: 86 | BQ6: 87 | BR6: 88 | BS6: 89 | BT6: 90 | BU6: 91 | BV6: 92 | BW6: 93 | BX6: 94 | BY6: 95 | BZ6: 96 | CA6: 97 | CB6: 98 | CC6: 99
A7: 300 | B7: 0.2 | C7: 0.5 | E7: 235 | F7: 235 | G7: 235 | H7: 235 | I7: 235 | J7: 235 | K7: 235 | L7: 235 | M7: 235 | N7: 235 | O7: 235 | P7: 235 | Q7: 235 | R7: 235 | S7: 235 | T7: 235 | U7: 235 | V7: 235 | W7: 235 | X7: 235 | Y7: 235 | Z7: 235 | AA7: 235 | AB7: 230 | AC7: 230 | AD7: 230 | AE7: 230 | AF7: 230 | AG7: 230 | AH7: 230 | AI7: 230 | AJ7: 230 | AK7: 230 | AL7: 230 | AM7: 230 | AN7: 230 | AO7: 230 | AP7: 230 | AQ7: 230 | AR7: 230 | AS7: 230 | AT7: 230 | AU7: 230 | AV7: 230 | AW7: 230 | AX7: 230 | AY7: 230 | AZ7: 230 | BA7: 230 | BB7: 230 | BC7: 230 | BD7: 255 | BE7: 255 | BF7: 255 | BG7: 255 | BH7: 255 | BI7: 255 | BJ7: 255 | BK7: 255 | BL7: 255 | BM7: 255 | BN7: 255 | BO7: 255 | BP7: 255 | BQ7: 255 | BR7: 255 | BS7: 255 | BT7: 275 | BU7: 275 | BV7: 275 | BW7: 275 | BX7: 275 | BY7: 275 | BZ7: 275 | CA7: 275 | CB7: 275 | CC7: 275
A8: 700 | B8: 0.4 | C8: 1 | E8: 235 | F8: 235 | G8: 235 | H8: 235 | I8: 235 | J8: 235 | K8: 235 | L8: 235 | M8: 235 | N8: 235 | O8: 235 | P8: 235 | Q8: 235 | R8: 235 | S8: 235 | T8: 235 | U8: 235 | V8: 235 | W8: 235 | X8: 235 | Y8: 235 | Z8: 235 | AA8: 235 | AB8: 230 | AC8: 230 | AD8: 230 | AE8: 230 | AF8: 230 | AG8: 230 | AH8: 230 | AI8: 230 | AJ8: 230 | AK8: 230 | AL8: 230 | AM8: 230 | AN8: 230 | AO8: 230 | AP8: 230 | AQ8: 230 | AR8: 230 | AS8: 230 | AT8: 230 | AU8: 230 | AV8: 230 | AW8: 230 | AX8: 230 | AY8: 230 | AZ8: 230 | BA8: 230 | BB8: 230 | BC8: 230 | BD8: 255 | BE8: 255 | BF8: 255 | BG8: 255 | BH8: 255 | BI8: 255 | BJ8: 255 | BK8: 255 | BL8: 255 | BM8: 255 | BN8: 255 | BO8: 255 | BP8: 255 | BQ8: 255 | BR8: 255 | BS8: 255 | BT8: 275 | BU8: 275 | BV8: 275 | BW8: 275 | BX8: 275 | BY8: 275 | BZ8: 275 | CA8: 275 | CB8: 275 | CC8: 275
A9: 875 | B9: 0.5 | D9: 1 | E9: 257 | F9: 257 | G9: 257 | H9: 257 | I9: 257 | J9: 257 | K9: 257 | L9: 257 | M9: 257 | N9: 257 | O9: 257 | P9: 257 | Q9: 257 | R9: 257 | S9: 257 | T9: 257 | U9: 257 | V9: 257 | W9: 257 | X9: 257 | Y9: 257 | Z9: 257 | AA9: 257 | AB9: 247 | AC9: 247 | AD9: 247 | AE9: 247 | AF9: 247 | AG9: 247 | AH9: 247 | AI9: 247 | AJ9: 247 | AK9: 247 | AL9: 247 | AM9: 247 | AN9: 247 | AO9: 247 | AP9: 247 | AQ9: 247 | AR9: 247 | AS9: 247 | AT9: 247 | AU9: 247 | AV9: 247 | AW9: 247 | AX9: 247 | AY9: 247 | AZ9: 247 | BA9: 247 | BB9: 247 | BC9: 247 | BD9: 277 | BE9: 277 | BF9: 277 | BG9: 277 | BH9: 277 | BI9: 277 | BJ9: 277 | BK9: 277 | BL9: 277 | BM9: 277 | BN9: 277 | BO9: 277 | BP9: 277 | BQ9: 277 | BR9: 277 | BS9: 277 | BT9: 303 | BU9: 303 | BV9: 303 | BW9: 303 | BX9: 303 | BY9: 303 | BZ9: 303 | CA9: 303 | CB9: 303 | CC9: 303
A10: 1050 | B10: 0.6 | E10: 304 | F10: 304 | G10: 304 | H10: 304 | I10: 304 | J10: 304 | K10: 304 | L10: 304 | M10: 304 | N10: 304 | O10: 304 | P10: 304 | Q10: 304 | R10: 304 | S10: 304 | T10: 304 | U10: 304 | V10: 304 | W10: 304 | X10: 304 | Y10: 304 | Z10: 304 | AA10: 304 | AB10: 265 | AC10: 265 | AD10: 265 | AE10: 265 | AF10: 265 | AG10: 265 | AH10: 265 | AI10: 265 | AJ10: 265 | AK10: 265 | AL10: 265 | AM10: 265 | AN10: 265 | AO10: 265 | AP10: 265 | AQ10: 265 | AR10: 265 | AS10: 265 | AT10: 284 | AU10: 284 | AV10: 284 | AW10: 284 | AX10: 284 | AY10: 284 | AZ10: 284 | BA10: 284 | BB10: 284 | BC10: 284 | BD10: 304 | BE10: 304 | BF10: 304 | BG10: 304 | BH10: 304 | BI10: 304 | BJ10: 319 | BK10: 319 | BL10: 319 | BM10: 319 | BN10: 319 | BO10: 319 | BP10: 319 | BQ10: 319 | BR10: 319 | BS10: 319 | BT10: 340 | BU10: 340 | BV10: 340 | BW10: 340 | BX10: 340 | BY10: 340 | BZ10: 340 | CA10: 340 | CB10: 340 | CC10: 340
A11: 1400 | B11: 0.8 | C11: 2 | E11: 371 | F11: 371 | G11: 371 | H11: 371 | I11: 371 | J11: 371 | K11: 371 | L11: 371 | M11: 371 | N11: 371 | O11: 371 | P11: 371 | Q11: 371 | R11: 371 | S11: 371 | T11: 371 | U11: 371 | V11: 371 | W11: 371 | X11: 371 | Y11: 371 | Z11: 371 | AA11: 371 | AB11: 290 | AC11: 290 | AD11: 290 | AE11: 290 | AF11: 290 | AG11: 290 | AH11: 290 | AI11: 290 | AJ11: 290 | AK11: 290 | AL11: 290 | AM11: 290 | AN11: 290 | AO11: 290 | AP11: 290 | AQ11: 290 | AR11: 290 | AS11: 290 | AT11: 345 | AU11: 345 | AV11: 345 | AW11: 345 | AX11: 345 | AY11: 345 | AZ11: 345 | BA11: 345 | BB11: 345 | BC11: 345 | BD11: 371 | BE11: 371 | BF11: 371 | BG11: 371 | BH11: 371 | BI11: 371 | BJ11: 391 | BK11: 391 | BL11: 391 | BM11: 391 | BN11: 391 | BO11: 391 | BP11: 391 | BQ11: 391 | BR11: 391 | BS11: 391 | BT11: 412 | BU11: 412 | BV11: 412 | BW11: 412 | BX11: 412 | BY11: 412 | BZ11: 412 | CA11: 412 | CB11: 412 | CC11: 412
A12: 1750 | B12: 1 | D12: 2 | E12: 448 | F12: 448 | G12: 448 | H12: 448 | I12: 448 | J12: 448 | K12: 448 | L12: 448 | M12: 448 | N12: 448 | O12: 448 | P12: 448 | Q12: 448 | R12: 448 | S12: 448 | T12: 448 | U12: 448 | V12: 448 | W12: 448 | X12: 448 | Y12: 448 | Z12: 448 | AA12: 448 | AB12: 359 | AC12: 359 | AD12: 359 | AE12: 359 | AF12: 359 | AG12: 359 | AH12: 359 | AI12: 359 | AJ12: 359 | AK12: 359 | AL12: 359 | AM12: 359 | AN12: 359 | AO12: 359 | AP12: 359 | AQ12: 359 | AR12: 359 | AS12: 359 | AT12: 415 | AU12: 415 | AV12: 415 | AW12: 415 | AX12: 415 | AY12: 415 | AZ12: 415 | BA12: 415 | BB12: 415 | BC12: 415 | BD12: 448 | BE12: 448 | BF12: 448 | BG12: 448 | BH12: 448 | BI12: 448 | BJ12: 463 | BK12: 463 | BL12: 463 | BM12: 463 | BN12: 463 | BO12: 463 | BP12: 463 | BQ12: 463 | BR12: 463 | BS12: 463 | BT12: 487 | BU12: 487 | BV12: 487 | BW12: 487 | BX12: 487 | BY12: 487 | BZ12: 487 | CA12: 487 | CB12: 487 | CC12: 487
A13: 2100 | B13: 1.2 | C13: 3 | E13: 472 | F13: 472 | G13: 472 | H13: 472 | I13: 472 | J13: 472 | K13: 472 | L13: 472 | M13: 472 | N13: 472 | O13: 472 | P13: 472 | Q13: 472 | R13: 472 | S13: 472 | T13: 472 | U13: 472 | V13: 472 | W13: 472 | X13: 472 | Y13: 472 | Z13: 472 | AA13: 472 | AB13: 384 | AC13: 384 | AD13: 384 | AE13: 384 | AF13: 384 | AG13: 384 | AH13: 384 | AI13: 384 | AJ13: 384 | AK13: 384 | AL13: 384 | AM13: 384 | AN13: 384 | AO13: 384 | AP13: 384 | AQ13: 384 | AR13: 384 | AS13: 384 | AT13: 456 | AU13: 456 | AV13: 456 | AW13: 456 | AX13: 456 | AY13: 456 | AZ13: 456 | BA13: 456 | BB13: 456 | BC13: 456 | BD13: 472 | BE13: 472 | BF13: 472 | BG13: 472 | BH13: 472 | BI13: 472 | BJ13: 489 | BK13: 489 | BL13: 489 | BM13: 489 | BN13: 489 | BO13: 489 | BP13: 489 | BQ13: 489 | BR13: 489 | BS13: 489 | BT13: 512 | BU13: 512 | BV13: 512 | BW13: 512 | BX13: 512 | BY13: 512 | BZ13: 512 | CA13: 512 | CB13: 512 | CC13: 512
A14: 2625 | B14: 1.5 | D14: 3 | E14: 550 | F14: 550 | G14: 550 | H14: 550 | I14: 550 | J14: 550 | K14: 550 | L14: 550 | M14: 550 | N14: 550 | O14: 550 | P14: 550 | Q14: 550 | R14: 550 | S14: 550 | T14: 550 | U14: 550 | V14: 550 | W14: 550 | X14: 550 | Y14: 550 | Z14: 550 | AA14: 550 | AB14: 463 | AC14: 463 | AD14: 463 | AE14: 463 | AF14: 463 | AG14: 463 | AH14: 463 | AI14: 463 | AJ14: 463 | AK14: 463 | AL14: 463 | AM14: 463 | AN14: 463 | AO14: 463 | AP14: 463 | AQ14: 463 | AR14: 463 | AS14: 463 | AT14: 527 | AU14: 527 | AV14: 527 | AW14: 527 | AX14: 527 | AY14: 527 | AZ14: 527 | BA14: 527 | BB14: 527 | BC14: 527 | BD14: 550 | BE14: 550 | BF14: 550 | BG14: 550 | BH14: 550 | BI14: 550 | BJ14: 574 | BK14: 574 | BL14: 574 | BM14: 574 | BN14: 574 | BO14: 574 | BP14: 574 | BQ14: 574 | BR14: 574 | BS14: 574 | BT14: 591 | BU14: 591 | BV14: 591 | BW14: 591 | BX14: 591 | BY14: 591 | BZ14: 591 | CA14: 591 | CB14: 591 | CC14: 591
A15: 2800 | B15: 1.6 | C15: 4 | E15: 561 | F15: 561 | G15: 561 | H15: 561 | I15: 561 | J15: 561 | K15: 561 | L15: 561 | M15: 561 | N15: 561 | O15: 561 | P15: 561 | Q15: 561 | R15: 561 | S15: 561 | T15: 561 | U15: 561 | V15: 561 | W15: 561 | X15: 561 | Y15: 561 | Z15: 561 | AA15: 561 | AB15: 466 | AC15: 466 | AD15: 466 | AE15: 466 | AF15: 466 | AG15: 466 | AH15: 466 | AI15: 466 | AJ15: 466 | AK15: 466 | AL15: 466 | AM15: 466 | AN15: 466 | AO15: 466 | AP15: 466 | AQ15: 466 | AR15: 466 | AS15: 466 | AT15: 536 | AU15: 536 | AV15: 536 | AW15: 536 | AX15: 536 | AY15: 536 | AZ15: 536 | BA15: 536 | BB15: 536 | BC15: 536 | BD15: 561 | BE15: 561 | BF15: 561 | BG15: 561 | BH15: 561 | BI15: 561 | BJ15: 615 | BK15: 615 | BL15: 615 | BM15: 615 | BN15: 615 | BO15: 615 | BP15: 615 | BQ15: 615 | BR15: 615 | BS15: 615 | BT15: 631 | BU15: 631 | BV15: 631 | BW15: 631 | BX15: 631 | BY15: 631 | BZ15: 631 | CA15: 631 | CB15: 631 | CC15: 631
A16: 3500 | B16: 2 | C16: 5 | D16: 4 | E16: 654 | F16: 654 | G16: 654 | H16: 654 | I16: 654 | J16: 654 | K16: 654 | L16: 654 | M16: 654 | N16: 654 | O16: 654 | P16: 654 | Q16: 654 | R16: 654 | S16: 654 | T16: 654 | U16: 654 | V16: 654 | W16: 654 | X16: 654 | Y16: 654 | Z16: 654 | AA16: 654 | AB16: 561 | AC16: 561 | AD16: 561 | AE16: 561 | AF16: 561 | AG16: 561 | AH16: 561 | AI16: 561 | AJ16: 561 | AK16: 561 | AL16: 561 | AM16: 561 | AN16: 561 | AO16: 561 | AP16: 561 | AQ16: 561 | AR16: 561 | AS16: 561 | AT16: 623 | AU16: 623 | AV16: 623 | AW16: 623 | AX16: 623 | AY16: 623 | AZ16: 623 | BA16: 623 | BB16: 623 | BC16: 623 | BD16: 654 | BE16: 654 | BF16: 654 | BG16: 654 | BH16: 654 | BI16: 654 | BJ16: 686 | BK16: 686 | BL16: 686 | BM16: 686 | BN16: 686 | BO16: 686 | BP16: 686 | BQ16: 686 | BR16: 686 | BS16: 686 | BT16: 702 | BU16: 702 | BV16: 702 | BW16: 702 | BX16: 702 | BY16: 702 | BZ16: 702 | CA16: 702 | CB16: 702 | CC16: 702
A17: 4200 | B17: 2.4 | C17: 6 | E17: 743 | F17: 743 | G17: 743 | H17: 743 | I17: 743 | J17: 743 | K17: 743 | L17: 743 | M17: 743 | N17: 743 | O17: 743 | P17: 743 | Q17: 743 | R17: 743 | S17: 743 | T17: 743 | U17: 743 | V17: 743 | W17: 743 | X17: 743 | Y17: 743 | Z17: 743 | AA17: 743 | AB17: 614 | AC17: 614 | AD17: 614 | AE17: 614 | AF17: 614 | AG17: 614 | AH17: 614 | AI17: 614 | AJ17: 614 | AK17: 614 | AL17: 614 | AM17: 614 | AN17: 614 | AO17: 614 | AP17: 614 | AQ17: 614 | AR17: 614 | AS17: 614 | AT17: 687 | AU17: 687 | AV17: 687 | AW17: 687 | AX17: 687 | AY17: 687 | AZ17: 687 | BA17: 687 | BB17: 687 | BC17: 687 | BD17: 743 | BE17: 743 | BF17: 743 | BG17: 743 | BH17: 743 | BI17: 743 | BJ17: 762 | BK17: 762 | BL17: 762 | BM17: 762 | BN17: 762 | BO17: 762 | BP17: 762 | BQ17: 762 | BR17: 762 | BS17: 762 | BT17: 774 | BU17: 774 | BV17: 774 | BW17: 774 | BX17: 774 | BY17: 774 | BZ17: 774 | CA17: 774 | CB17: 774 | CC17: 774
A18: 4375 | B18: 2.5 | D18: 5 | E18: 760 | F18: 760 | G18: 760 | H18: 760 | I18: 760 | J18: 760 | K18: 760 | L18: 760 | M18: 760 | N18: 760 | O18: 760 | P18: 760 | Q18: 760 | R18: 760 | S18: 760 | T18: 760 | U18: 760 | V18: 760 | W18: 760 | X18: 760 | Y18: 760 | Z18: 760 | AA18: 760 | AB18: 617 | AC18: 617 | AD18: 617 | AE18: 617 | AF18: 617 | AG18: 617 | AH18: 617 | AI18: 617 | AJ18: 617 | AK18: 617 | AL18: 617 | AM18: 617 | AN18: 617 | AO18: 617 | AP18: 617 | AQ18: 617 | AR18: 617 | AS18: 617 | AT18: 699 | AU18: 699 | AV18: 699 | AW18: 699 | AX18: 699 | AY18: 699 | AZ18: 699 | BA18: 699 | BB18: 699 | BC18: 699 | BD18: 760 | BE18: 760 | BF18: 760 | BG18: 760 | BH18: 760 | BI18: 760 | BJ18: 774 | BK18: 774 | BL18: 774 | BM18: 774 | BN18: 774 | BO18: 774 | BP18: 774 | BQ18: 774 | BR18: 774 | BS18: 774 | BT18: 791 | BU18: 791 | BV18: 791 | BW18: 791 | BX18: 791 | BY18: 791 | BZ18: 791 | CA18: 791 | CB18: 791 | CC18: 791
A19: 4900 | B19: 2.8 | C19: 7 | E19: 774 | F19: 774 | G19: 774 | H19: 774 | I19: 774 | J19: 774 | K19: 774 | L19: 774 | M19: 774 | N19: 774 | O19: 774 | P19: 774 | Q19: 774 | R19: 774 | S19: 774 | T19: 774 | U19: 774 | V19: 774 | W19: 774 | X19: 774 | Y19: 774 | Z19: 774 | AA19: 774 | AB19: 638 | AC19: 638 | AD19: 638 | AE19: 638 | AF19: 638 | AG19: 638 | AH19: 638 | AI19: 638 | AJ19: 638 | AK19: 638 | AL19: 638 | AM19: 638 | AN19: 638 | AO19: 638 | AP19: 638 | AQ19: 638 | AR19: 638 | AS19: 638 | AT19: 707 | AU19: 707 | AV19: 707 | AW19: 707 | AX19: 707 | AY19: 707 | AZ19: 707 | BA19: 707 | BB19: 707 | BC19: 707 | BD19: 774 | BE19: 774 | BF19: 774 | BG19: 774 | BH19: 774 | BI19: 774 | BJ19: 799 | BK19: 799 | BL19: 799 | BM19: 799 | BN19: 799 | BO19: 799 | BP19: 799 | BQ19: 799 | BR19: 799 | BS19: 799 | BT19: 821 | BU19: 821 | BV19: 821 | BW19: 821 | BX19: 821 | BY19: 821 | BZ19: 821 | CA19: 821 | CB19: 821 | CC19: 821
A20: 5250 | B20: 3 | D20: 6 | E20: 809 | F20: 809 | G20: 809 | H20: 809 | I20: 809 | J20: 809 | K20: 809 | L20: 809 | M20: 809 | N20: 809 | O20: 809 | P20: 809 | Q20: 809 | R20: 809 | S20: 809 | T20: 809 | U20: 809 | V20: 809 | W20: 809 | X20: 809 | Y20: 809 | Z20: 809 | AA20: 809 | AB20: 644 | AC20: 644 | AD20: 644 | AE20: 644 | AF20: 644 | AG20: 644 | AH20: 644 | AI20: 644 | AJ20: 644 | AK20: 644 | AL20: 644 | AM20: 644 | AN20: 644 | AO20: 644 | AP20: 644 | AQ20: 644 | AR20: 644 | AS20: 644 | AT20: 716 | AU20: 716 | AV20: 716 | AW20: 716 | AX20: 716 | AY20: 716 | AZ20: 716 | BA20: 716 | BB20: 716 | BC20: 716 | BD20: 809 | BE20: 809 | BF20: 809 | BG20: 809 | BH20: 809 | BI20: 809 | BJ20: 836 | BK20: 836 | BL20: 836 | BM20: 836 | BN20: 836 | BO20: 836 | BP20: 836 | BQ20: 836 | BR20: 836 | BS20: 836 | BT20: 854 | BU20: 854 | BV20: 854 | BW20: 854 | BX20: 854 | BY20: 854 | BZ20: 854 | CA20: 854 | CB20: 854 | CC20: 854
A21: 5600 | B21: 3.2 | C21: 8 | E21: 839 | F21: 839 | G21: 839 | H21: 839 | I21: 839 | J21: 839 | K21: 839 | L21: 839 | M21: 839 | N21: 839 | O21: 839 | P21: 839 | Q21: 839 | R21: 839 | S21: 839 | T21: 839 | U21: 839 | V21: 839 | W21: 839 | X21: 839 | Y21: 839 | Z21: 839 | AA21: 839 | AB21: 690 | AC21: 690 | AD21: 690 | AE21: 690 | AF21: 690 | AG21: 690 | AH21: 690 | AI21: 690 | AJ21: 690 | AK21: 690 | AL21: 690 | AM21: 690 | AN21: 690 | AO21: 690 | AP21: 690 | AQ21: 690 | AR21: 690 | AS21: 690 | AT21: 740 | AU21: 740 | AV21: 740 | AW21: 740 | AX21: 740 | AY21: 740 | AZ21: 740 | BA21: 740 | BB21: 740 | BC21: 740 | BD21: 839 | BE21: 839 | BF21: 839 | BG21: 839 | BH21: 839 | BI21: 839 | BJ21: 870 | BK21: 870 | BL21: 870 | BM21: 870 | BN21: 870 | BO21: 870 | BP21: 870 | BQ21: 870 | BR21: 870 | BS21: 870 | BT21: 885 | BU21: 885 | BV21: 885 | BW21: 885 | BX21: 885 | BY21: 885 | BZ21: 885 | CA21: 885 | CB21: 885 | CC21: 885
A22: 6125 | B22: 3.5 | D22: 7 | E22: 863 | F22: 863 | G22: 863 | H22: 863 | I22: 863 | J22: 863 | K22: 863 | L22: 863 | M22: 863 | N22: 863 | O22: 863 | P22: 863 | Q22: 863 | R22: 863 | S22: 863 | T22: 863 | U22: 863 | V22: 863 | W22: 863 | X22: 863 | Y22: 863 | Z22: 863 | AA22: 863 | AB22: 732 | AC22: 732 | AD22: 732 | AE22: 732 | AF22: 732 | AG22: 732 | AH22: 732 | AI22: 732 | AJ22: 732 | AK22: 732 | AL22: 732 | AM22: 732 | AN22: 732 | AO22: 732 | AP22: 732 | AQ22: 732 | AR22: 732 | AS22: 732 | AT22: 770 | AU22: 770 | AV22: 770 | AW22: 770 | AX22: 770 | AY22: 770 | AZ22: 770 | BA22: 770 | BB22: 770 | BC22: 770 | BD22: 863 | BE22: 863 | BF22: 863 | BG22: 863 | BH22: 863 | BI22: 863 | BJ22: 893 | BK22: 893 | BL22: 893 | BM22: 893 | BN22: 893 | BO22: 893 | BP22: 893 | BQ22: 893 | BR22: 893 | BS22: 893 | BT22: 894 | BU22: 894 | BV22: 894 | BW22: 894 | BX22: 894 | BY22: 894 | BZ22: 894 | CA22: 894 | CB22: 894 | CC22: 894
A23: 6300 | B23: 3.6 | C23: 9 | E23: 893 | F23: 893 | G23: 893 | H23: 893 | I23: 893 | J23: 893 | K23: 893 | L23: 893 | M23: 893 | N23: 893 | O23: 893 | P23: 893 | Q23: 893 | R23: 893 | S23: 893 | T23: 893 | U23: 893 | V23: 893 | W23: 893 | X23: 893 | Y23: 893 | Z23: 893 | AA23: 893 | AB23: 748 | AC23: 748 | AD23: 748 | AE23: 748 | AF23: 748 | AG23: 748 | AH23: 748 | AI23: 748 | AJ23: 748 | AK23: 748 | AL23: 748 | AM23: 748 | AN23: 748 | AO23: 748 | AP23: 748 | AQ23: 748 | AR23: 748 | AS23: 748 | AT23: 804 | AU23: 804 | AV23: 804 | AW23: 804 | AX23: 804 | AY23: 804 | AZ23: 804 | BA23: 804 | BB23: 804 | BC23: 804 | BD23: 893 | BE23: 893 | BF23: 893 | BG23: 893 | BH23: 893 | BI23: 893 | BJ23: 915 | BK23: 915 | BL23: 915 | BM23: 915 | BN23: 915 | BO23: 915 | BP23: 915 | BQ23: 915 | BR23: 915 | BS23: 915 | BT23: 910 | BU23: 910 | BV23: 910 | BW23: 910 | BX23: 910 | BY23: 910 | BZ23: 910 | CA23: 910 | CB23: 910 | CC23: 910
A24: 7000 | B24: 4 | C24: 10 | D24: 8 | E24: 940 | F24: 940 | G24: 940 | H24: 940 | I24: 940 | J24: 940 | K24: 940 | L24: 940 | M24: 940 | N24: 940 | O24: 940 | P24: 940 | Q24: 940 | R24: 940 | S24: 940 | T24: 940 | U24: 940 | V24: 940 | W24: 940 | X24: 940 | Y24: 940 | Z24: 940 | AA24: 940 | AB24: 793 | AC24: 793 | AD24: 793 | AE24: 793 | AF24: 793 | AG24: 793 | AH24: 793 | AI24: 793 | AJ24: 793 | AK24: 793 | AL24: 793 | AM24: 793 | AN24: 793 | AO24: 793 | AP24: 793 | AQ24: 793 | AR24: 793 | AS24: 793 | AT24: 840 | AU24: 840 | AV24: 840 | AW24: 840 | AX24: 840 | AY24: 840 | AZ24: 840 | BA24: 840 | BB24: 840 | BC24: 840 | BD24: 940 | BE24: 940 | BF24: 940 | BG24: 940 | BH24: 940 | BI24: 940 | BJ24: 969 | BK24: 969 | BL24: 969 | BM24: 969 | BN24: 969 | BO24: 969 | BP24: 969 | BQ24: 969 | BR24: 969 | BS24: 969 | BT24: 985 | BU24: 985 | BV24: 985 | BW24: 985 | BX24: 985 | BY24: 985 | BZ24: 985 | CA24: 985 | CB24: 985 | CC24: 985
A26: Transittijden:
A28: Dag van lading is dag 0 | C28: Vertrek | G28: Transittijd in werkdagen | T28: Transittijd in werkdagen | AG28: Transittijd in werkdagen | AT28: Transittijd in werkdagen | BG28: Transittijd in werkdagen | BT28: Transittijd in werkdagen
A29: Groupage 1-5 pallets | C29: ma,di,wo,do,vrij | E29: 2/3 | F29: 2/3 | G29: 2/3 | H29: 2/3 | I29: 2/3 | J29: 2/3 | K29: 2/3 | L29: 2/3 | M29: 2/3 | N29: 2/3 | O29: 2/3 | P29: 2/3 | Q29: 2/3 | R29: 2/3 | S29: 2/3 | T29: 2/3 | U29: 2/3 | V29: 2/3 | W29: 2/3 | X29: 2/3 | Y29: 2/3 | Z29: 2/3 | AA29: 2/3 | AB29: 2/3 | AC29: 2/3 | AD29: 2/3 | AE29: 2/3 | AF29: 2/3 | AG29: 2/3 | AH29: 2/3 | AI29: 2/3 | AJ29: 2/3 | AK29: 2/3 | AL29: 2/3 | AM29: 2/3 | AN29: 2/3 | AO29: 2/3 | AP29: 2/3 | AQ29: 2/3 | AR29: 2/3 | AS29: 2/3 | AT29: 3/4 | AU29: 3/4 | AV29: 3/4 | AW29: 3/4 | AX29: 3/4 | AY29: 3/4 | AZ29: 3/4 | BA29: 3/4 | BB29: 3/4 | BC29: 3/4 | BD29: 2/3 | BE29: 2/3 | BF29: 2/3 | BG29: 2/3 | BH29: 2/3 | BI29: 2/3 | BJ29: 2/3 | BK29: 2/3 | BL29: 2/3 | BM29: 2/3 | BN29: 2/3 | BO29: 2/3 | BP29: 2/3 | BQ29: 2/3 | BR29: 2/3 | BS29: 2/3 | BT29: 3/4 | BU29: 3/4 | BV29: 3/4 | BW29: 3/4 | BX29: 3/4 | BY29: 3/4 | BZ29: 3/4 | CA29: 3/4 | CB29: 3/4 | CC29: 3/4
A30: Deelpartijen > 5 pallets | C30: ma,di,wo,do,vrij | E30: 2 | F30: 2 | G30: 2 | H30: 2 | I30: 2 | J30: 2 | K30: 2 | L30: 2 | M30: 2 | N30: 2 | O30: 2 | P30: 2 | Q30: 2 | R30: 2 | S30: 2 | T30: 2 | U30: 2 | V30: 2 | W30: 2 | X30: 2 | Y30: 2 | Z30: 2 | AA30: 2 | AB30: 2 | AC30: 2 | AD30: 2 | AE30: 2 | AF30: 2 | AG30: 2 | AH30: 2 | AI30: 2 | AJ30: 2 | AK30: 2 | AL30: 2 | AM30: 2 | AN30: 2 | AO30: 2 | AP30: 2 | AQ30: 2 | AR30: 2 | AS30: 2 | AT30: 3 | AU30: 3 | AV30: 3 | AW30: 3 | AX30: 3 | AY30: 3 | AZ30: 3 | BA30: 3 | BB30: 3 | BC30: 3 | BD30: 2 | BE30: 2 | BF30: 2 | BG30: 2 | BH30: 2 | BI30: 2 | BJ30: 2 | BK30: 2 | BL30: 2 | BM30: 2 | BN30: 2 | BO30: 2 | BP30: 2 | BQ30: 2 | BR30: 2 | BS30: 2 | BT30: 3 | BU30: 3 | BV30: 3 | BW30: 3 | BX30: 3 | BY30: 3 | BZ30: 3 | CA30: 3 | CB30: 3 | CC30: 3
A31: Compleet ladingen | C31: ma,di,wo,do,vrij | E31: 1/2 | F31: 1/2 | G31: 1/2 | H31: 1/2 | I31: 1/2 | J31: 1/2 | K31: 1/2 | L31: 1/2 | M31: 1/2 | N31: 1/2 | O31: 1/2 | P31: 1/2 | Q31: 1/2 | R31: 1/2 | S31: 1/2 | T31: 1/2 | U31: 1/2 | V31: 1/2 | W31: 1/2 | X31: 1/2 | Y31: 1/2 | Z31: 1/2 | AA31: 1/2 | AB31: 1/2 | AC31: 1/2 | AD31: 1/2 | AE31: 1/2 | AF31: 1/2 | AG31: 1/2 | AH31: 1/2 | AI31: 1/2 | AJ31: 1/2 | AK31: 1/2 | AL31: 1/2 | AM31: 1/2 | AN31: 1/2 | AO31: 1/2 | AP31: 1/2 | AQ31: 1/2 | AR31: 1/2 | AS31: 1/2 | AT31: 2/3 | AU31: 2/3 | AV31: 2/3 | AW31: 2/3 | AX31: 2/3 | AY31: 2/3 | AZ31: 2/3 | BA31: 2/3 | BB31: 2/3 | BC31: 2/3 | BD31: 1/2 | BE31: 1/2 | BF31: 1/2 | BG31: 1/2 | BH31: 1/2 | BI31: 1/2 | BJ31: 1/2 | BK31: 1/2 | BL31: 1/2 | BM31: 1/2 | BN31: 1/2 | BO31: 1/2 | BP31: 1/2 | BQ31: 1/2 | BR31: 1/2 | BS31: 1/2 | BT31: 2/3 | BU31: 2/3 | BV31: 2/3 | BW31: 2/3 | BX31: 2/3 | BY31: 2/3 | BZ31: 2/3 | CA31: 2/3 | CB31: 2/3 | CC31: 2/3

Sheet BE
A3: =Voorblad!A5 -> Team Freight Forwarding Logistics
A4: Export België
A6: kg | B6: ldm | C6: euplt | D6: blkplt | E6: BE
A7: 300 | B7: 0.2 | C7: 0.5 | E7: 104
A8: 700 | B8: 0.4 | C8: 1 | E8: 110
A9: 875 | B9: 0.5 | D9: 1 | E9: 118
A10: 1050 | B10: 0.6 | E10: 136
A11: 1400 | B11: 0.8 | C11: 2 | E11: 155
A12: 1750 | B12: 1 | D12: 2 | E12: 181
A13: 2100 | B13: 1.2 | C13: 3 | E13: 206
A14: 2625 | B14: 1.5 | D14: 3 | E14: 216
A15: 2800 | B15: 1.6 | C15: 4 | E15: 223
A16: 3500 | B16: 2 | C16: 5 | D16: 4 | E16: 257
A17: 4200 | B17: 2.4 | C17: 6 | E17: 377
A18: 4375 | B18: 2.5 | D18: 5 | E18: 383
A19: 4900 | B19: 2.8 | C19: 7 | E19: 400
A20: 5250 | B20: 3 | D20: 6 | E20: 416
A21: 5600 | B21: 3.2 | C21: 8 | E21: 452
A22: 6125 | B22: 3.5 | D22: 7 | E22: 460
A23: 6300 | B23: 3.6 | C23: 9 | E23: 472
A24: 7000 | B24: 4 | C24: 10 | D24: 8 | E24: 487
A26: Transittijden:
A28: Dag van lading is dag 0 | C28: Vertrek | E28: Transittijd in werkdagen
A29: Groupage 1-5 pallets | C29: ma,di,wo,do,vrij | E29: 1/2
A30: Deelpartijen > 5 pallets | C30: ma,di,wo,do,vrij | E30: 1/2
A31: Compleet ladingen | C31: ma,di,wo,do,vrij | E31: 1

Sheet BG
A3: =Voorblad!A5 -> Team Freight Forwarding Logistics
A4: Export Bulgarije
A6: kg | B6: ldm | C6: euplt | D6: blkplt | E6: 10 | F6: 11 | G6: 12 | H6: 13 | I6: 14 | J6: 15 | K6: 16 | L6: 17 | M6: 18 | N6: 20 | O6: 21 | P6: 22 | Q6: 23 | R6: 24 | S6: 25 | T6: 26 | U6: 27 | V6: 28 | W6: 29 | X6: 30 | Y6: 31 | Z6: 32 | AA6: 33 | AB6: 34 | AC6: 35 | AD6: 36 | AE6: 37 | AF6: 38 | AG6: 39 | AH6: 40 | AI6: 41 | AJ6: 42 | AK6: 43 | AL6: 44 | AM6: 45 | AN6: 46 | AO6: 47 | AP6: 48 | AQ6: 49 | AR6: 50 | AS6: 51 | AT6: 52 | AU6: 53 | AV6: 54 | AW6: 55 | AX6: 56 | AY6: 57 | AZ6: 58 | BA6: 59 | BB6: 60 | BC6: 61 | BD6: 62 | BE6: 63 | BF6: 64 | BG6: 65 | BH6: 66 | BI6: 67 | BJ6: 68 | BK6: 69 | BL6: 70 | BM6: 71 | BN6: 72 | BO6: 73 | BP6: 74 | BQ6: 75 | BR6: 76 | BS6: 77 | BT6: 78 | BU6: 79 | BV6: 80 | BW6: 81 | BX6: 82 | BY6: 83 | BZ6: 84 | CA6: 85 | CB6: 86 | CC6: 87 | CD6: 88 | CE6: 89 | CF6: 90 | CG6: 91 | CH6: 92 | CI6: 93 | CJ6: 94 | CK6: 95 | CL6: 96 | CM6: 97 | CN6: 98 | CO6: 99
A7: 300 | B7: 0.2 | C7: 0.5 | E7: 199 | F7: 199 | G7: 199 | H7: 199 | I7: 199 | J7: 199 | K7: 199 | L7: 199 | M7: 199 | N7: 229 | O7: 229 | P7: 229 | Q7: 229 | R7: 229 | S7: 229 | T7: 229 | U7: 229 | V7: 229 | W7: 229 | X7: 229 | Y7: 229 | Z7: 229 | AA7: 229 | AB7: 229 | AC7: 229 | AD7: 229 | AE7: 229 | AF7: 229 | AG7: 229 | AH7: 229 | AI7: 229 | AJ7: 229 | AK7: 229 | AL7: 229 | AM7: 229 | AN7: 229 | AO7: 229 | AP7: 229 | AQ7: 229 | AR7: 229 | AS7: 229 | AT7: 229 | AU7: 229 | AV7: 229 | AW7: 229 | AX7: 229 | AY7: 229 | AZ7: 229 | BA7: 229 | BB7: 229 | BC7: 229 | BD7: 229 | BE7: 229 | BF7: 229 | BG7: 229 | BH7: 229 | BI7: 229 | BJ7: 229 | BK7: 229 | BL7: 229 | BM7: 229 | BN7: 229 | BO7: 229 | BP7: 229 | BQ7: 229 | BR7: 229 | BS7: 229 | BT7: 229 | BU7: 229 | BV7: 229 | BW7: 229 | BX7: 229 | BY7: 229 | BZ7: 229 | CA7: 229 | CB7: 229 | CC7: 229 | CD7: 229 | CE7: 229 | CF7: 229 | CG7: 229 | CH7: 229 | CI7: 229 | CJ7: 229 | CK7: 229 | CL7: 229 | CM7: 229 | CN7: 229 | CO7: 229
A8: 700 | B8: 0.4 | C8: 1 | E8: 229 | F8: 229 | G8: 229 | H8: 229 | I8: 229 | J8: 229 | K8: 229 | L8: 229 | M8: 229 | N8: 263 | O8: 263 | P8: 263 | Q8: 263 | R8: 263 | S8: 263 | T8: 263 | U8: 263 | V8: 263 | W8: 263 | X8: 263 | Y8: 263 | Z8: 263 | AA8: 263 | AB8: 263 | AC8: 263 | AD8: 263 | AE8: 263 | AF8: 263 | AG8: 263 | AH8: 263 | AI8: 263 | AJ8: 263 | AK8: 263 | AL8: 263 | AM8: 263 | AN8: 263 | AO8: 263 | AP8: 263 | AQ8: 263 | AR8: 263 | AS8: 263 | AT8: 263 | AU8: 263 | AV8: 263 | AW8: 263 | AX8: 263 | AY8: 263 | AZ8: 263 | BA8: 263 | BB8: 263 | BC8: 263 | BD8: 263 | BE8: 263 | BF8: 263 | BG8: 263 | BH8: 263 | BI8: 263 | BJ8: 263 | BK8: 263 | BL8: 263 | BM8: 263 | BN8: 263 | BO8: 263 | BP8: 263 | BQ8: 263 | BR8: 263 | BS8: 263 | BT8: 263 | BU8: 263 | BV8: 263 | BW8: 263 | BX8: 263 | BY8: 263 | BZ8: 263 | CA8: 263 | CB8: 263 | CC8: 263 | CD8: 263 | CE8: 263 | CF8: 263 | CG8: 263 | CH8: 263 | CI8: 263 | CJ8: 263 | CK8: 263 | CL8: 263 | CM8: 263 | CN8: 263 | CO8: 263
A9: 875 | B9: 0.5 | D9: 1 | E9: 263 | F9: 263 | G9: 263 | H9: 263 | I9: 263 | J9: 263 | K9: 263 | L9: 263 | M9: 263 | N9: 296 | O9: 296 | P9: 296 | Q9: 296 | R9: 296 | S9: 296 | T9: 296 | U9: 296 | V9: 296 | W9: 296 | X9: 296 | Y9: 296 | Z9: 296 | AA9: 296 | AB9: 296 | AC9: 296 | AD9: 296 | AE9: 296 | AF9: 296 | AG9: 296 | AH9: 296 | AI9: 296 | AJ9: 296 | AK9: 296 | AL9: 296 | AM9: 296 | AN9: 296 | AO9: 296 | AP9: 296 | AQ9: 296 | AR9: 296 | AS9: 296 | AT9: 296 | AU9: 296 | AV9: 296 | AW9: 296 | AX9: 296 | AY9: 296 | AZ9: 296 | BA9: 296 | BB9: 296 | BC9: 296 | BD9: 296 | BE9: 296 | BF9: 296 | BG9: 296 | BH9: 296 | BI9: 296 | BJ9: 296 | BK9: 296 | BL9: 296 | BM9: 296 | BN9: 296 | BO9: 296 | BP9: 296 | BQ9: 296 | BR9: 296 | BS9: 296 | BT9: 296 | BU9: 296 | BV9: 296 | BW9: 296 | BX9: 296 | BY9: 296 | BZ9: 296 | CA9: 296 | CB9: 296 | CC9: 296 | CD9: 296 | CE9: 296 | CF9: 296 | CG9: 296 | CH9: 296 | CI9: 296 | CJ9: 296 | CK9: 296 | CL9: 296 | CM9: 296 | CN9: 296 | CO9: 296
A10: 1050 | B10: 0.6 | E10: 311 | F10: 311 | G10: 311 | H10: 311 | I10: 311 | J10: 311 | K10: 311 | L10: 311 | M10: 311 | N10: 398 | O10: 398 | P10: 398 | Q10: 398 | R10: 398 | S10: 398 | T10: 398 | U10: 398 | V10: 398 | W10: 398 | X10: 398 | Y10: 398 | Z10: 398 | AA10: 398 | AB10: 398 | AC10: 398 | AD10: 398 | AE10: 398 | AF10: 398 | AG10: 398 | AH10: 398 | AI10: 398 | AJ10: 398 | AK10: 398 | AL10: 398 | AM10: 433 | AN10: 433 | AO10: 433 | AP10: 433 | AQ10: 433 | AR10: 398 | AS10: 398 | AT10: 398 | AU10: 398 | AV10: 398 | AW10: 398 | AX10: 398 | AY10: 398 | AZ10: 398 | BA10: 398 | BB10: 433 | BC10: 433 | BD10: 433 | BE10: 433 | BF10: 433 | BG10: 433 | BH10: 433 | BI10: 433 | BJ10: 433 | BK10: 433 | BL10: 433 | BM10: 433 | BN10: 433 | BO10: 433 | BP10: 433 | BQ10: 433 | BR10: 433 | BS10: 433 | BT10: 433 | BU10: 433 | BV10: 433 | BW10: 433 | BX10: 433 | BY10: 433 | BZ10: 433 | CA10: 433 | CB10: 433 | CC10: 433 | CD10: 433 | CE10: 433 | CF10: 433 | CG10: 433 | CH10: 433 | CI10: 433 | CJ10: 433 | CK10: 433 | CL10: 433 | CM10: 433 | CN10: 433 | CO10: 433
A11: 1400 | B11: 0.8 | C11: 2 | E11: 352 | F11: 352 | G11: 352 | H11: 352 | I11: 352 | J11: 352 | K11: 352 | L11: 352 | M11: 352 | N11: 468 | O11: 468 | P11: 468 | Q11: 468 | R11: 468 | S11: 468 | T11: 468 | U11: 468 | V11: 468 | W11: 468 | X11: 468 | Y11: 468 | Z11: 468 | AA11: 468 | AB11: 468 | AC11: 468 | AD11: 468 | AE11: 468 | AF11: 468 | AG11: 468 | AH11: 468 | AI11: 468 | AJ11: 468 | AK11: 468 | AL11: 468 | AM11: 502 | AN11: 502 | AO11: 502 | AP11: 502 | AQ11: 502 | AR11: 468 | AS11: 468 | AT11: 468 | AU11: 468 | AV11: 468 | AW11: 468 | AX11: 468 | AY11: 468 | AZ11: 468 | BA11: 468 | BB11: 502 | BC11: 502 | BD11: 502 | BE11: 502 | BF11: 502 | BG11: 502 | BH11: 502 | BI11: 502 | BJ11: 502 | BK11: 502 | BL11: 502 | BM11: 502 | BN11: 502 | BO11: 502 | BP11: 502 | BQ11: 502 | BR11: 502 | BS11: 502 | BT11: 502 | BU11: 502 | BV11: 502 | BW11: 502 | BX11: 502 | BY11: 502 | BZ11: 502 | CA11: 502 | CB11: 502 | CC11: 502 | CD11: 502 | CE11: 502 | CF11: 502 | CG11: 502 | CH11: 502 | CI11: 502 | CJ11: 502 | CK11: 502 | CL11: 502 | CM11: 502 | CN11: 502 | CO11: 502
A12: 1750 | B12: 1 | D12: 2 | E12: 410 | F12: 410 | G12: 410 | H12: 410 | I12: 410 | J12: 410 | K12: 410 | L12: 410 | M12: 410 | N12: 526 | O12: 526 | P12: 526 | Q12: 526 | R12: 526 | S12: 526 | T12: 526 | U12: 526 | V12: 526 | W12: 526 | X12: 526 | Y12: 526 | Z12: 526 | AA12: 526 | AB12: 526 | AC12: 526 | AD12: 526 | AE12: 526 | AF12: 526 | AG12: 526 | AH12: 526 | AI12: 526 | AJ12: 526 | AK12: 526 | AL12: 526 | AM12: 562 | AN12: 562 | AO12: 562 | AP12: 562 | AQ12: 562 | AR12: 526 | AS12: 526 | AT12: 526 | AU12: 526 | AV12: 526 | AW12: 526 | AX12: 526 | AY12: 526 | AZ12: 526 | BA12: 526 | BB12: 562 | BC12: 562 | BD12: 562 | BE12: 562 | BF12: 562 | BG12: 562 | BH12: 562 | BI12: 562 | BJ12: 562 | BK12: 562 | BL12: 562 | BM12: 562 | BN12: 562 | BO12: 562 | BP12: 562 | BQ12: 562 | BR12: 562 | BS12: 562 | BT12: 562 | BU12: 562 | BV12: 562 | BW12: 562 | BX12: 562 | BY12: 562 | BZ12: 562 | CA12: 562 | CB12: 562 | CC12: 562 | CD12: 562 | CE12: 562 | CF12: 562 | CG12: 562 | CH12: 562 | CI12: 562 | CJ12: 562 | CK12: 562 | CL12: 562 | CM12: 562 | CN12: 562 | CO12: 562
A13: 2100 | B13: 1.2 | C13: 3 | E13: 468 | F13: 468 | G13: 468 | H13: 468 | I13: 468 | J13: 468 | K13: 468 | L13: 468 | M13: 468 | N13: 586 | O13: 586 | P13: 586 | Q13: 586 | R13: 586 | S13: 586 | T13: 586 | U13: 586 | V13: 586 | W13: 586 | X13: 586 | Y13: 586 | Z13: 586 | AA13: 586 | AB13: 586 | AC13: 586 | AD13: 586 | AE13: 586 | AF13: 586 | AG13: 586 | AH13: 586 | AI13: 586 | AJ13: 586 | AK13: 586 | AL13: 586 | AM13: 620 | AN13: 620 | AO13: 620 | AP13: 620 | AQ13: 620 | AR13: 586 | AS13: 586 | AT13: 586 | AU13: 586 | AV13: 586 | AW13: 586 | AX13: 586 | AY13: 586 | AZ13: 586 | BA13: 586 | BB13: 620 | BC13: 620 | BD13: 620 | BE13: 620 | BF13: 620 | BG13: 620 | BH13: 620 | BI13: 620 | BJ13: 620 | BK13: 620 | BL13: 620 | BM13: 620 | BN13: 620 | BO13: 620 | BP13: 620 | BQ13: 620 | BR13: 620 | BS13: 620 | BT13: 620 | BU13: 620 | BV13: 620 | BW13: 620 | BX13: 620 | BY13: 620 | BZ13: 620 | CA13: 620 | CB13: 620 | CC13: 620 | CD13: 620 | CE13: 620 | CF13: 620 | CG13: 620 | CH13: 620 | CI13: 620 | CJ13: 620 | CK13: 620 | CL13: 620 | CM13: 620 | CN13: 620 | CO13: 620
A14: 2625 | B14: 1.5 | D14: 3 | E14: 526 | F14: 526 | G14: 526 | H14: 526 | I14: 526 | J14: 526 | K14: 526 | L14: 526 | M14: 526 | N14: 643 | O14: 643 | P14: 643 | Q14: 643 | R14: 643 | S14: 643 | T14: 643 | U14: 643 | V14: 643 | W14: 643 | X14: 643 | Y14: 643 | Z14: 643 | AA14: 643 | AB14: 643 | AC14: 643 | AD14: 643 | AE14: 643 | AF14: 643 | AG14: 643 | AH14: 643 | AI14: 643 | AJ14: 643 | AK14: 643 | AL14: 643 | AM14: 678 | AN14: 678 | AO14: 678 | AP14: 678 | AQ14: 678 | AR14: 643 | AS14: 643 | AT14: 643 | AU14: 643 | AV14: 643 | AW14: 643 | AX14: 643 | AY14: 643 | AZ14: 643 | BA14: 643 | BB14: 678 | BC14: 678 | BD14: 678 | BE14: 678 | BF14: 678 | BG14: 678 | BH14: 678 | BI14: 678 | BJ14: 678 | BK14: 678 | BL14: 678 | BM14: 678 | BN14: 678 | BO14: 678 | BP14: 678 | BQ14: 678 | BR14: 678 | BS14: 678 | BT14: 678 | BU14: 678 | BV14: 678 | BW14: 678 | BX14: 678 | BY14: 678 | BZ14: 678 | CA14: 678 | CB14: 678 | CC14: 678 | CD14: 678 | CE14: 678 | CF14: 678 | CG14: 678 | CH14: 678 | CI14: 678 | CJ14: 678 | CK14: 678 | CL14: 678 | CM14: 678 | CN14: 678 | CO14: 678
A15: 2800 | B15: 1.6 | C15: 4 | E15: 586 | F15: 586 | G15: 586 | H15: 586 | I15: 586 | J15: 586 | K15: 586 | L15: 586 | M15: 586 | N15: 702 | O15: 702 | P15: 702 | Q15: 702 | R15: 702 | S15: 702 | T15: 702 | U15: 702 | V15: 702 | W15: 702 | X15: 702 | Y15: 702 | Z15: 702 | AA15: 702 | AB15: 702 | AC15: 702 | AD15: 702 | AE15: 702 | AF15: 702 | AG15: 702 | AH15: 702 | AI15: 702 | AJ15: 702 | AK15: 702 | AL15: 702 | AM15: 759 | AN15: 759 | AO15: 759 | AP15: 759 | AQ15: 759 | AR15: 702 | AS15: 702 | AT15: 702 | AU15: 702 | AV15: 702 | AW15: 702 | AX15: 702 | AY15: 702 | AZ15: 702 | BA15: 702 | BB15: 759 | BC15: 759 | BD15: 759 | BE15: 759 | BF15: 759 | BG15: 759 | BH15: 759 | BI15: 759 | BJ15: 759 | BK15: 759 | BL15: 759 | BM15: 759 | BN15: 759 | BO15: 759 | BP15: 759 | BQ15: 759 | BR15: 759 | BS15: 759 | BT15: 759 | BU15: 759 | BV15: 759 | BW15: 759 | BX15: 759 | BY15: 759 | BZ15: 759 | CA15: 759 | CB15: 759 | CC15: 759 | CD15: 759 | CE15: 759 | CF15: 759 | CG15: 759 | CH15: 759 | CI15: 759 | CJ15: 759 | CK15: 759 | CL15: 759 | CM15: 759 | CN15: 759 | CO15: 759
A16: 3500 | B16: 2 | C16: 5 | D16: 4 | E16: 643 | F16: 643 | G16: 643 | H16: 643 | I16: 643 | J16: 643 | K16: 643 | L16: 643 | M16: 643 | N16: 759 | O16: 759 | P16: 759 | Q16: 759 | R16: 759 | S16: 759 | T16: 759 | U16: 759 | V16: 759 | W16: 759 | X16: 759 | Y16: 759 | Z16: 759 | AA16: 759 | AB16: 759 | AC16: 759 | AD16: 759 | AE16: 759 | AF16: 759 | AG16: 759 | AH16: 759 | AI16: 759 | AJ16: 759 | AK16: 759 | AL16: 759 | AM16: 818 | AN16: 818 | AO16: 818 | AP16: 818 | AQ16: 818 | AR16: 759 | AS16: 759 | AT16: 759 | AU16: 759 | AV16: 759 | AW16: 759 | AX16: 759 | AY16: 759 | AZ16: 759 | BA16: 759 | BB16: 818 | BC16: 818 | BD16: 818 | BE16: 818 | BF16: 818 | BG16: 818 | BH16: 818 | BI16: 818 | BJ16: 818 | BK16: 818 | BL16: 818 | BM16: 818 | BN16: 818 | BO16: 818 | BP16: 818 | BQ16: 818 | BR16: 818 | BS16: 818 | BT16: 818 | BU16: 818 | BV16: 818 | BW16: 818 | BX16: 818 | BY16: 818 | BZ16: 818 | CA16: 818 | CB16: 818 | CC16: 818 | CD16: 818 | CE16: 818 | CF16: 818 | CG16: 818 | CH16: 818 | CI16: 818 | CJ16: 818 | CK16: 818 | CL16: 818 | CM16: 818 | CN16: 818 | CO16: 818
A17: 4200 | B17: 2.4 | C17: 6 | E17: 660 | F17: 660 | G17: 660 | H17: 660 | I17: 660 | J17: 660 | K17: 660 | L17: 660 | M17: 660 | N17: 770 | O17: 770 | P17: 770 | Q17: 770 | R17: 770 | S17: 770 | T17: 770 | U17: 770 | V17: 770 | W17: 770 | X17: 770 | Y17: 770 | Z17: 770 | AA17: 770 | AB17: 770 | AC17: 770 | AD17: 770 | AE17: 770 | AF17: 770 | AG17: 770 | AH17: 770 | AI17: 770 | AJ17: 770 | AK17: 770 | AL17: 770 | AM17: 825 | AN17: 825 | AO17: 825 | AP17: 825 | AQ17: 825 | AR17: 770 | AS17: 770 | AT17: 770 | AU17: 770 | AV17: 770 | AW17: 770 | AX17: 770 | AY17: 770 | AZ17: 770 | BA17: 770 | BB17: 825 | BC17: 825 | BD17: 825 | BE17: 825 | BF17: 825 | BG17: 825 | BH17: 825 | BI17: 825 | BJ17: 825 | BK17: 825 | BL17: 825 | BM17: 825 | BN17: 825 | BO17: 825 | BP17: 825 | BQ17: 825 | BR17: 825 | BS17: 825 | BT17: 825 | BU17: 825 | BV17: 825 | BW17: 825 | BX17: 825 | BY17: 825 | BZ17: 825 | CA17: 825 | CB17: 825 | CC17: 825 | CD17: 825 | CE17: 825 | CF17: 825 | CG17: 825 | CH17: 825 | CI17: 825 | CJ17: 825 | CK17: 825 | CL17: 825 | CM17: 825 | CN17: 825 | CO17: 825
A18: 4375 | B18: 2.5 | D18: 5 | E18: 714 | F18: 714 | G18: 714 | H18: 714 | I18: 714 | J18: 714 | K18: 714 | L18: 714 | M18: 714 | N18: 825 | O18: 825 | P18: 825 | Q18: 825 | R18: 825 | S18: 825 | T18: 825 | U18: 825 | V18: 825 | W18: 825 | X18: 825 | Y18: 825 | Z18: 825 | AA18: 825 | AB18: 825 | AC18: 825 | AD18: 825 | AE18: 825 | AF18: 825 | AG18: 825 | AH18: 825 | AI18: 825 | AJ18: 825 | AK18: 825 | AL18: 825 | AM18: 880 | AN18: 880 | AO18: 880 | AP18: 880 | AQ18: 880 | AR18: 825 | AS18: 825 | AT18: 825 | AU18: 825 | AV18: 825 | AW18: 825 | AX18: 825 | AY18: 825 | AZ18: 825 | BA18: 825 | BB18: 880 | BC18: 880 | BD18: 880 | BE18: 880 | BF18: 880 | BG18: 880 | BH18: 880 | BI18: 880 | BJ18: 880 | BK18: 880 | BL18: 880 | BM18: 880 | BN18: 880 | BO18: 880 | BP18: 880 | BQ18: 880 | BR18: 880 | BS18: 880 | BT18: 880 | BU18: 880 | BV18: 880 | BW18: 880 | BX18: 880 | BY18: 880 | BZ18: 880 | CA18: 880 | CB18: 880 | CC18: 880 | CD18: 880 | CE18: 880 | CF18: 880 | CG18: 880 | CH18: 880 | CI18: 880 | CJ18: 880 | CK18: 880 | CL18: 880 | CM18: 880 | CN18: 880 | CO18: 880
A19: 4900 | B19: 2.8 | C19: 7 | E19: 770 | F19: 770 | G19: 770 | H19: 770 | I19: 770 | J19: 770 | K19: 770 | L19: 770 | M19: 770 | N19: 880 | O19: 880 | P19: 880 | Q19: 880 | R19: 880 | S19: 880 | T19: 880 | U19: 880 | V19: 880 | W19: 880 | X19: 880 | Y19: 880 | Z19: 880 | AA19: 880 | AB19: 880 | AC19: 880 | AD19: 880 | AE19: 880 | AF19: 880 | AG19: 880 | AH19: 880 | AI19: 880 | AJ19: 880 | AK19: 880 | AL19: 880 | AM19: 935 | AN19: 935 | AO19: 935 | AP19: 935 | AQ19: 935 | AR19: 880 | AS19: 880 | AT19: 880 | AU19: 880 | AV19: 880 | AW19: 880 | AX19: 880 | AY19: 880 | AZ19: 880 | BA19: 880 | BB19: 935 | BC19: 935 | BD19: 935 | BE19: 935 | BF19: 935 | BG19: 935 | BH19: 935 | BI19: 935 | BJ19: 935 | BK19: 935 | BL19: 935 | BM19: 935 | BN19: 935 | BO19: 935 | BP19: 935 | BQ19: 935 | BR19: 935 | BS19: 935 | BT19: 935 | BU19: 935 | BV19: 935 | BW19: 935 | BX19: 935 | BY19: 935 | BZ19: 935 | CA19: 935 | CB19: 935 | CC19: 935 | CD19: 935 | CE19: 935 | CF19: 935 | CG19: 935 | CH19: 935 | CI19: 935 | CJ19: 935 | CK19: 935 | CL19: 935 | CM19: 935 | CN19: 935 | CO19: 935
A20: 5250 | B20: 3 | D20: 6 | E20: 825 | F20: 825 | G20: 825 | H20: 825 | I20: 825 | J20: 825 | K20: 825 | L20: 825 | M20: 825 | N20: 935 | O20: 935 | P20: 935 | Q20: 935 | R20: 935 | S20: 935 | T20: 935 | U20: 935 | V20: 935 | W20: 935 | X20: 935 | Y20: 935 | Z20: 935 | AA20: 935 | AB20: 935 | AC20: 935 | AD20: 935 | AE20: 935 | AF20: 935 | AG20: 935 | AH20: 935 | AI20: 935 | AJ20: 935 | AK20: 935 | AL20: 935 | AM20: 990 | AN20: 990 | AO20: 990 | AP20: 990 | AQ20: 990 | AR20: 935 | AS20: 935 | AT20: 935 | AU20: 935 | AV20: 935 | AW20: 935 | AX20: 935 | AY20: 935 | AZ20: 935 | BA20: 935 | BB20: 990 | BC20: 990 | BD20: 990 | BE20: 990 | BF20: 990 | BG20: 990 | BH20: 990 | BI20: 990 | BJ20: 990 | BK20: 990 | BL20: 990 | BM20: 990 | BN20: 990 | BO20: 990 | BP20: 990 | BQ20: 990 | BR20: 990 | BS20: 990 | BT20: 990 | BU20: 990 | BV20: 990 | BW20: 990 | BX20: 990 | BY20: 990 | BZ20: 990 | CA20: 990 | CB20: 990 | CC20: 990 | CD20: 990 | CE20: 990 | CF20: 990 | CG20: 990 | CH20: 990 | CI20: 990 | CJ20: 990 | CK20: 990 | CL20: 990 | CM20: 990 | CN20: 990 | CO20: 990
A21: 5600 | B21: 3.2 | C21: 8 | E21: 880 | F21: 880 | G21: 880 | H21: 880 | I21: 880 | J21: 880 | K21: 880 | L21: 880 | M21: 880 | N21: 990 | O21: 990 | P21: 990 | Q21: 990 | R21: 990 | S21: 990 | T21: 990 | U21: 990 | V21: 990 | W21: 990 | X21: 990 | Y21: 990 | Z21: 990 | AA21: 990 | AB21: 990 | AC21: 990 | AD21: 990 | AE21: 990 | AF21: 990 | AG21: 990 | AH21: 990 | AI21: 990 | AJ21: 990 | AK21: 990 | AL21: 990 | AM21: 1044 | AN21: 1044 | AO21: 1044 | AP21: 1044 | AQ21: 1044 | AR21: 990 | AS21: 990 | AT21: 990 | AU21: 990 | AV21: 990 | AW21: 990 | AX21: 990 | AY21: 990 | AZ21: 990 | BA21: 990 | BB21: 1044 | BC21: 1044 | BD21: 1044 | BE21: 1044 | BF21: 1044 | BG21: 1044 | BH21: 1044 | BI21: 1044 | BJ21: 1044 | BK21: 1044 | BL21: 1044 | BM21: 1044 | BN21: 1044 | BO21: 1044 | BP21: 1044 | BQ21: 1044 | BR21: 1044 | BS21: 1044 | BT21: 1044 | BU21: 1044 | BV21: 1044 | BW21: 1044 | BX21: 1044 | BY21: 1044 | BZ21: 1044 | CA21: 1044 | CB21: 1044 | CC21: 1044 | CD21: 1044 | CE21: 1044 | CF21: 1044 | CG21: 1044 | CH21: 1044 | CI21: 1044 | CJ21: 1044 | CK21: 1044 | CL21: 1044 | CM21: 1044 | CN21: 1044 | CO21: 1044
A22: 6125 | B22: 3.5 | D22: 7 | E22: 935 | F22: 935 | G22: 935 | H22: 935 | I22: 935 | J22: 935 | K22: 935 | L22: 935 | M22: 935 | N22: 1044 | O22: 1044 | P22: 1044 | Q22: 1044 | R22: 1044 | S22: 1044 | T22: 1044 | U22: 1044 | V22: 1044 | W22: 1044 | X22: 1044 | Y22: 1044 | Z22: 1044 | AA22: 1044 | AB22: 1044 | AC22: 1044 | AD22: 1044 | AE22: 1044 | AF22: 1044 | AG22: 1044 | AH22: 1044 | AI22: 1044 | AJ22: 1044 | AK22: 1044 | AL22: 1044 | AM22: 1099 | AN22: 1099 | AO22: 1099 | AP22: 1099 | AQ22: 1099 | AR22: 1044 | AS22: 1044 | AT22: 1044 | AU22: 1044 | AV22: 1044 | AW22: 1044 | AX22: 1044 | AY22: 1044 | AZ22: 1044 | BA22: 1044 | BB22: 1099 | BC22: 1099 | BD22: 1099 | BE22: 1099 | BF22: 1099 | BG22: 1099 | BH22: 1099 | BI22: 1099 | BJ22: 1099 | BK22: 1099 | BL22: 1099 | BM22: 1099 | BN22: 1099 | BO22: 1099 | BP22: 1099 | BQ22: 1099 | BR22: 1099 | BS22: 1099 | BT22: 1099 | BU22: 1099 | BV22: 1099 | BW22: 1099 | BX22: 1099 | BY22: 1099 | BZ22: 1099 | CA22: 1099 | CB22: 1099 | CC22: 1099 | CD22: 1099 | CE22: 1099 | CF22: 1099 | CG22: 1099 | CH22: 1099 | CI22: 1099 | CJ22: 1099 | CK22: 1099 | CL22: 1099 | CM22: 1099 | CN22: 1099 | CO22: 1099
A23: 6300 | B23: 3.6 | C23: 9 | E23: 990 | F23: 990 | G23: 990 | H23: 990 | I23: 990 | J23: 990 | K23: 990 | L23: 990 | M23: 990 | N23: 1099 | O23: 1099 | P23: 1099 | Q23: 1099 | R23: 1099 | S23: 1099 | T23: 1099 | U23: 1099 | V23: 1099 | W23: 1099 | X23: 1099 | Y23: 1099 | Z23: 1099 | AA23: 1099 | AB23: 1099 | AC23: 1099 | AD23: 1099 | AE23: 1099 | AF23: 1099 | AG23: 1099 | AH23: 1099 | AI23: 1099 | AJ23: 1099 | AK23: 1099 | AL23: 1099 | AM23: 1187 | AN23: 1187 | AO23: 1187 | AP23: 1187 | AQ23: 1187 | AR23: 1099 | AS23: 1099 | AT23: 1099 | AU23: 1099 | AV23: 1099 | AW23: 1099 | AX23: 1099 | AY23: 1099 | AZ23: 1099 | BA23: 1099 | BB23: 1187 | BC23: 1187 | BD23: 1187 | BE23: 1187 | BF23: 1187 | BG23: 1187 | BH23: 1187 | BI23: 1187 | BJ23: 1187 | BK23: 1187 | BL23: 1187 | BM23: 1187 | BN23: 1187 | BO23: 1187 | BP23: 1187 | BQ23: 1187 | BR23: 1187 | BS23: 1187 | BT23: 1187 | BU23: 1187 | BV23: 1187 | BW23: 1187 | BX23: 1187 | BY23: 1187 | BZ23: 1187 | CA23: 1187 | CB23: 1187 | CC23: 1187 | CD23: 1187 | CE23: 1187 | CF23: 1187 | CG23: 1187 | CH23: 1187 | CI23: 1187 | CJ23: 1187 | CK23: 1187 | CL23: 1187 | CM23: 1187 | CN23: 1187 | CO23: 1187
A24: 7000 | B24: 4 | C24: 10 | D24: 8 | E24: 1044 | F24: 1044 | G24: 1044 | H24: 1044 | I24: 1044 | J24: 1044 | K24: 1044 | L24: 1044 | M24: 1044 | N24: 1154 | O24: 1154 | P24: 1154 | Q24: 1154 | R24: 1154 | S24: 1154 | T24: 1154 | U24: 1154 | V24: 1154 | W24: 1154 | X24: 1154 | Y24: 1154 | Z24: 1154 | AA24: 1154 | AB24: 1154 | AC24: 1154 | AD24: 1154 | AE24: 1154 | AF24: 1154 | AG24: 1154 | AH24: 1154 | AI24: 1154 | AJ24: 1154 | AK24: 1154 | AL24: 1154 | AM24: 1275 | AN24: 1275 | AO24: 1275 | AP24: 1275 | AQ24: 1275 | AR24: 1154 | AS24: 1154 | AT24: 1154 | AU24: 1154 | AV24: 1154 | AW24: 1154 | AX24: 1154 | AY24: 1154 | AZ24: 1154 | BA24: 1154 | BB24: 1275 | BC24: 1275 | BD24: 1275 | BE24: 1275 | BF24: 1275 | BG24: 1275 | BH24: 1275 | BI24: 1275 | BJ24: 1275 | BK24: 1275 | BL24: 1275 | BM24: 1275 | BN24: 1275 | BO24: 1275 | BP24: 1275 | BQ24: 1275 | BR24: 1275 | BS24: 1275 | BT24: 1275 | BU24: 1275 | BV24: 1275 | BW24: 1275 | BX24: 1275 | BY24: 1275 | BZ24: 1275 | CA24: 1275 | CB24: 1275 | CC24: 1275 | CD24: 1275 | CE24: 1275 | CF24: 1275 | CG24: 1275 | CH24: 1275 | CI24: 1275 | CJ24: 1275 | CK24: 1275 | CL24: 1275 | CM24: 1275 | CN24: 1275 | CO24: 1275
A26: Transittijden:
A28: Dag van lading is dag 0 | C28: Vertrek | G28: Transittijd in werkdagen | T28: Transittijd in werkdagen | AG28: Transittijd in werkdagen | AT28: Transittijd in werkdagen | BG28: Transittijd in werkdagen | BT28: Transittijd in werkdagen | CG28: Transittijd in werkdagen
A29: Groupage 1-5 pallets | C29: di,do,vrij | E29: 5 | F29: 5 | G29: 5 | H29: 5 | I29: 5 | J29: 5 | K29: 5 | L29: 5 | M29: 5 | N29: 5 | O29: 5 | P29: 5 | Q29: 5 | R29: 5 | S29: 5 | T29: 5 | U29: 5 | V29: 5 | W29: 5 | X29: 5 | Y29: 5 | Z29: 5 | AA29: 5 | AB29: 5 | AC29: 5 | AD29: 5 | AE29: 5 | AF29: 5 | AG29: 5 | AH29: 5/6 | AI29: 5/6 | AJ29: 5/6 | AK29: 5/6 | AL29: 5 | AM29: 5/6 | AN29: 5 | AO29: 5/6 | AP29: 5/6 | AQ29: 5/6 | AR29: 5/6 | AS29: 5/6 | AT29: 5/6 | AU29: 5/6 | AV29: 5/6 | AW29: 5/6 | AX29: 5/6 | AY29: 5/6 | AZ29: 5/6 | BA29: 5/6 | BB29: 5/6 | BC29: 5/6 | BD29: 5/6 | BE29: 5/6 | BF29: 5/6 | BG29: 5/6 | BH29: 5/6 | BI29: 5/6 | BJ29: 5/6 | BK29: 5/6 | BL29: 5/6 | BM29: 5/6 | BN29: 5/6 | BO29: 5/6 | BP29: 5/6 | BQ29: 5/6 | BR29: 5/6 | BS29: 5/6 | BT29: 5/6 | BU29: 5/6 | BV29: 5/6 | BW29: 5/6 | BX29: 5/6 | BY29: 5/6 | BZ29: 5/6 | CA29: 5/6 | CB29: 5/6 | CC29: 5/6 | CD29: 5/6 | CE29: 5/6 | CF29: 5/6 | CG29: 5/6 | CH29: 5/6 | CI29: 5/6 | CJ29: 5/6 | CK29: 5/6 | CL29: 5/6 | CM29: 5/6 | CN29: 5/6 | CO29: 5/6
A30: Deelpartijen > 5 pallets | C30: di,wo,do,vrij | E30: 4/5 | F30: 4/5 | G30: 4/5 | H30: 4/5 | I30: 4/5 | J30: 4/5 | K30: 4/5 | L30: 4/5 | M30: 4/5 | N30: 4/5 | O30: 4/5 | P30: 4/5 | Q30: 4/5 | R30: 4/5 | S30: 4/5 | T30: 4/5 | U30: 4/5 | V30: 4/5 | W30: 4/5 | X30: 4/5 | Y30: 4/5 | Z30: 4/5 | AA30: 4/5 | AB30: 4/5 | AC30: 4/5 | AD30: 4/5 | AE30: 4/5 | AF30: 4/5 | AG30: 4/5 | AH30: 5 | AI30: 5 | AJ30: 5 | AK30: 5 | AL30: 4/5 | AM30: 5 | AN30: 4/5 | AO30: 5 | AP30: 5 | AQ30: 5 | AR30: 5 | AS30: 5 | AT30: 5 | AU30: 5 | AV30: 5 | AW30: 5 | AX30: 5 | AY30: 5 | AZ30: 5 | BA30: 5 | BB30: 5 | BC30: 5 | BD30: 5 | BE30: 5 | BF30: 5 | BG30: 5 | BH30: 5 | BI30: 5 | BJ30: 5 | BK30: 5 | BL30: 5 | BM30: 5 | BN30: 5 | BO30: 5 | BP30: 5 | BQ30: 5 | BR30: 5 | BS30: 5 | BT30: 5 | BU30: 5 | BV30: 5 | BW30: 5 | BX30: 5 | BY30: 5 | BZ30: 5 | CA30: 5 | CB30: 5 | CC30: 5 | CD30: 5 | CE30: 5 | CF30: 5 | CG30: 5 | CH30: 5 | CI30: 5 | CJ30: 5 | CK30: 5 | CL30: 5 | CM30: 5 | CN30: 5 | CO30: 5
A31: Compleet ladingen | C31: ma,di,wo,do,vrij | E31: 4 | F31: 4 | G31: 4 | H31: 4 | I31: 4 | J31: 4 | K31: 4 | L31: 4 | M31: 4 | N31: 4 | O31: 4 | P31: 4 | Q31: 4 | R31: 4 | S31: 4 | T31: 4 | U31: 4 | V31: 4 | W31: 4 | X31: 4 | Y31: 4 | Z31: 4 | AA31: 4 | AB31: 4 | AC31: 4 | AD31: 4 | AE31: 4 | AF31: 4 | AG31: 4 | AH31: 4 | AI31: 4 | AJ31: 4 | AK31: 4 | AL31: 4 | AM31: 4 | AN31: 4 | AO31: 4 | AP31: 4 | AQ31: 4 | AR31: 4 | AS31: 4 | AT31: 4 | AU31: 4 | AV31: 4 | AW31: 4 | AX31: 4 | AY31: 4 | AZ31: 4 | BA31: 4 | BB31: 4 | BC31: 4 | BD31: 4 | BE31: 4 | BF31: 4 | BG31: 4 | BH31: 4 | BI31: 4 | BJ31: 4 | BK31: 4 | BL31: 4 | BM31: 4 | BN31: 4 | BO31: 4 | BP31: 4 | BQ31: 4 | BR31: 4 | BS31: 4 | BT31: 4 | BU31: 4 | BV31: 4 | BW31: 4 | BX31: 4 | BY31: 4 | BZ31: 4 | CA31: 4 | CB31: 4 | CC31: 4 | CD31: 4 | CE31: 4 | CF31: 4 | CG31: 4 | CH31: 4 | CI31: 4 | CJ31: 4 | CK31: 4 | CL31: 4 | CM31: 4 | CN31: 4 | CO31: 4

Sheet CH
A3: =Voorblad!A5 -> Team Freight Forwarding Logistics
A4: Export Zwitserland
A6: kg | B6: ldm | C6: euplt | D6: blkplt | E6: 10 | F6: 11 | G6: 12 | H6: 13 | I6: 14 | J6: 15 | K6: 16 | L6: 17 | M6: 18 | N6: 19 | O6: 20 | P6: 21 | Q6: 22 | R6: 23 | S6: 24 | T6: 25 | U6: 26 | V6: 27 | W6: 28 | X6: 29 | Y6: 30 | Z6: 31 | AA6: 32 | AB6: 33 | AC6: 34 | AD6: 35 | AE6: 36 | AF6: 37 | AG6: 38 | AH6: 39 | AI6: 40 | AJ6: 41 | AK6: 42 | AL6: 43 | AM6: 44 | AN6: 45 | AO6: 46 | AP6: 47 | AQ6: 48 | AR6: 49 | AS6: 50 | AT6: 51 | AU6: 52 | AV6: 53 | AW6: 54 | AX6: 55 | AY6: 56 | AZ6: 57 | BA6: 60 | BB6: 61 | BC6: 62 | BD6: 63 | BE6: 64 | BF6: 65 | BG6: 66 | BH6: 67 | BI6: 68 | BJ6: 69 | BK6: 70 | BL6: 71 | BM6: 72 | BN6: 73 | BO6: 74 | BP6: 75 | BQ6: 76 | BR6: 77 | BS6: 80 | BT6: 81 | BU6: 82 | BV6: 83 | BW6: 84 | BX6: 85 | BY6: 86 | BZ6: 87 | CA6: 88 | CB6: 89 | CC6: 90 | CD6: 91 | CE6: 92 | CF6: 93 | CG6: 94 | CH6: 95 | CI6: 96
A7: 300 | B7: 0.2 | C7: 0.5 | E7: 231 | F7: 231 | G7: 250 | H7: 231 | I7: 213 | J7: 213 | K7: 213 | L7: 213 | M7: 231 | N7: 250 | O7: 193 | P7: 193 | Q7: 193 | R7: 193 | S7: 193 | T7: 193 | U7: 193 | V7: 193 | W7: 193 | X7: 193 | Y7: 193 | Z7: 193 | AA7: 193 | AB7: 193 | AC7: 193 | AD7: 193 | AE7: 213 | AF7: 213 | AG7: 213 | AH7: 287 | AI7: 157 | AJ7: 157 | AK7: 157 | AL7: 157 | AM7: 157 | AN7: 172 | AO7: 172 | AP7: 172 | AQ7: 172 | AR7: 172 | AS7: 172 | AT7: 172 | AU7: 172 | AV7: 172 | AW7: 172 | AX7: 172 | AY7: 193 | AZ7: 193 | BA7: 193 | BB7: 193 | BC7: 193 | BD7: 193 | BE7: 213 | BF7: 270 | BG7: 270 | BH7: 250 | BI7: 270 | BJ7: 270 | BK7: 231 | BL7: 287 | BM7: 250 | BN7: 250 | BO7: 287 | BP7: 287 | BQ7: 287 | BR7: 287 | BS7: 193 | BT7: 193 | BU7: 193 | BV7: 193 | BW7: 193 | BX7: 213 | BY7: 213 | BZ7: 213 | CA7: 213 | CB7: 193 | CC7: 213 | CD7: 213 | CE7: 213 | CF7: 213 | CG7: 213 | CH7: 213 | CI7: 213
A8: 700 | B8: 0.4 | C8: 1 | E8: 320 | F8: 320 | G8: 348 | H8: 320 | I8: 292 | J8: 292 | K8: 292 | L8: 292 | M8: 320 | N8: 348 | O8: 257 | P8: 257 | Q8: 257 | R8: 257 | S8: 257 | T8: 257 | U8: 257 | V8: 257 | W8: 257 | X8: 257 | Y8: 257 | Z8: 257 | AA8: 257 | AB8: 257 | AC8: 257 | AD8: 257 | AE8: 292 | AF8: 292 | AG8: 292 | AH8: 402 | AI8: 203 | AJ8: 203 | AK8: 203 | AL8: 203 | AM8: 203 | AN8: 221 | AO8: 221 | AP8: 221 | AQ8: 221 | AR8: 221 | AS8: 221 | AT8: 221 | AU8: 221 | AV8: 221 | AW8: 221 | AX8: 221 | AY8: 257 | AZ8: 257 | BA8: 257 | BB8: 257 | BC8: 257 | BD8: 257 | BE8: 292 | BF8: 379 | BG8: 379 | BH8: 348 | BI8: 379 | BJ8: 379 | BK8: 320 | BL8: 402 | BM8: 348 | BN8: 348 | BO8: 402 | BP8: 402 | BQ8: 402 | BR8: 402 | BS8: 257 | BT8: 257 | BU8: 257 | BV8: 257 | BW8: 257 | BX8: 292 | BY8: 292 | BZ8: 292 | CA8: 292 | CB8: 257 | CC8: 292 | CD8: 292 | CE8: 292 | CF8: 292 | CG8: 292 | CH8: 292 | CI8: 292
A9: 875 | B9: 0.5 | D9: 1 | E9: 411 | F9: 411 | G9: 451 | H9: 411 | I9: 374 | J9: 374 | K9: 374 | L9: 374 | M9: 411 | N9: 451 | O9: 315 | P9: 315 | Q9: 315 | R9: 315 | S9: 315 | T9: 315 | U9: 315 | V9: 315 | W9: 315 | X9: 315 | Y9: 315 | Z9: 315 | AA9: 315 | AB9: 315 | AC9: 315 | AD9: 315 | AE9: 374 | AF9: 374 | AG9: 374 | AH9: 520 | AI9: 230 | AJ9: 230 | AK9: 230 | AL9: 230 | AM9: 230 | AN9: 240 | AO9: 240 | AP9: 240 | AQ9: 240 | AR9: 240 | AS9: 240 | AT9: 240 | AU9: 240 | AV9: 240 | AW9: 240 | AX9: 240 | AY9: 315 | AZ9: 315 | BA9: 315 | BB9: 315 | BC9: 315 | BD9: 315 | BE9: 374 | BF9: 490 | BG9: 490 | BH9: 451 | BI9: 490 | BJ9: 490 | BK9: 411 | BL9: 520 | BM9: 451 | BN9: 451 | BO9: 520 | BP9: 520 | BQ9: 520 | BR9: 520 | BS9: 315 | BT9: 315 | BU9: 315 | BV9: 315 | BW9: 315 | BX9: 374 | BY9: 374 | BZ9: 374 | CA9: 374 | CB9: 315 | CC9: 374 | CD9: 374 | CE9: 374 | CF9: 374 | CG9: 374 | CH9: 374 | CI9: 374
A10: 1050 | B10: 0.6 | E10: 471 | F10: 471 | G10: 513 | H10: 471 | I10: 421 | J10: 421 | K10: 421 | L10: 421 | M10: 471 | N10: 513 | O10: 350 | P10: 350 | Q10: 350 | R10: 350 | S10: 350 | T10: 350 | U10: 350 | V10: 350 | W10: 350 | X10: 350 | Y10: 350 | Z10: 350 | AA10: 350 | AB10: 350 | AC10: 350 | AD10: 350 | AE10: 421 | AF10: 421 | AG10: 421 | AH10: 591 | AI10: 265 | AJ10: 265 | AK10: 265 | AL10: 265 | AM10: 265 | AN10: 272 | AO10: 272 | AP10: 272 | AQ10: 272 | AR10: 272 | AS10: 272 | AT10: 272 | AU10: 272 | AV10: 272 | AW10: 272 | AX10: 272 | AY10: 350 | AZ10: 350 | BA10: 350 | BB10: 350 | BC10: 350 | BD10: 350 | BE10: 421 | BF10: 557 | BG10: 557 | BH10: 513 | BI10: 557 | BJ10: 557 | BK10: 471 | BL10: 591 | BM10: 513 | BN10: 513 | BO10: 591 | BP10: 591 | BQ10: 591 | BR10: 591 | BS10: 350 | BT10: 350 | BU10: 350 | BV10: 350 | BW10: 350 | BX10: 421 | BY10: 421 | BZ10: 421 | CA10: 421 | CB10: 350 | CC10: 421 | CD10: 421 | CE10: 421 | CF10: 421 | CG10: 421 | CH10: 421 | CI10: 421
A11: 1400 | B11: 0.8 | C11: 2 | E11: 531 | F11: 531 | G11: 576 | H11: 531 | I11: 468 | J11: 468 | K11: 468 | L11: 468 | M11: 531 | N11: 576 | O11: 380 | P11: 380 | Q11: 380 | R11: 380 | S11: 380 | T11: 380 | U11: 380 | V11: 380 | W11: 380 | X11: 380 | Y11: 380 | Z11: 380 | AA11: 380 | AB11: 380 | AC11: 380 | AD11: 380 | AE11: 468 | AF11: 468 | AG11: 468 | AH11: 665 | AI11: 297 | AJ11: 297 | AK11: 297 | AL11: 297 | AM11: 297 | AN11: 306 | AO11: 306 | AP11: 306 | AQ11: 306 | AR11: 306 | AS11: 306 | AT11: 306 | AU11: 306 | AV11: 306 | AW11: 306 | AX11: 306 | AY11: 380 | AZ11: 380 | BA11: 380 | BB11: 380 | BC11: 380 | BD11: 380 | BE11: 468 | BF11: 626 | BG11: 626 | BH11: 576 | BI11: 626 | BJ11: 626 | BK11: 531 | BL11: 665 | BM11: 576 | BN11: 576 | BO11: 665 | BP11: 665 | BQ11: 665 | BR11: 665 | BS11: 380 | BT11: 380 | BU11: 380 | BV11: 380 | BW11: 380 | BX11: 468 | BY11: 468 | BZ11: 468 | CA11: 468 | CB11: 380 | CC11: 468 | CD11: 468 | CE11: 468 | CF11: 468 | CG11: 468 | CH11: 468 | CI11: 468
A12: 1750 | B12: 1 | D12: 2 | E12: 568 | F12: 568 | G12: 613 | H12: 568 | I12: 504 | J12: 504 | K12: 504 | L12: 504 | M12: 568 | N12: 613 | O12: 416 | P12: 416 | Q12: 416 | R12: 416 | S12: 416 | T12: 416 | U12: 416 | V12: 416 | W12: 416 | X12: 416 | Y12: 416 | Z12: 416 | AA12: 416 | AB12: 416 | AC12: 416 | AD12: 416 | AE12: 504 | AF12: 504 | AG12: 504 | AH12: 701 | AI12: 333 | AJ12: 333 | AK12: 333 | AL12: 333 | AM12: 333 | AN12: 340 | AO12: 340 | AP12: 340 | AQ12: 340 | AR12: 340 | AS12: 340 | AT12: 340 | AU12: 340 | AV12: 340 | AW12: 340 | AX12: 340 | AY12: 416 | AZ12: 416 | BA12: 416 | BB12: 416 | BC12: 416 | BD12: 416 | BE12: 504 | BF12: 663 | BG12: 663 | BH12: 613 | BI12: 663 | BJ12: 663 | BK12: 568 | BL12: 701 | BM12: 613 | BN12: 613 | BO12: 701 | BP12: 701 | BQ12: 701 | BR12: 701 | BS12: 416 | BT12: 416 | BU12: 416 | BV12: 416 | BW12: 416 | BX12: 504 | BY12: 504 | BZ12: 504 | CA12: 504 | CB12: 416 | CC12: 504 | CD12: 504 | CE12: 504 | CF12: 504 | CG12: 504 | CH12: 504 | CI12: 504
A13: 2100 | B13: 1.2 | C13: 3 | E13: 648 | F13: 648 | G13: 643 | H13: 648 | I13: 533 | J13: 533 | K13: 533 | L13: 533 | M13: 648 | N13: 643 | O13: 448 | P13: 448 | Q13: 448 | R13: 448 | S13: 448 | T13: 448 | U13: 448 | V13: 448 | W13: 448 | X13: 448 | Y13: 448 | Z13: 448 | AA13: 448 | AB13: 448 | AC13: 448 | AD13: 448 | AE13: 533 | AF13: 533 | AG13: 533 | AH13: 727 | AI13: 364 | AJ13: 364 | AK13: 364 | AL13: 364 | AM13: 364 | AN13: 370 | AO13: 370 | AP13: 370 | AQ13: 370 | AR13: 370 | AS13: 370 | AT13: 370 | AU13: 370 | AV13: 370 | AW13: 370 | AX13: 370 | AY13: 448 | AZ13: 448 | BA13: 448 | BB13: 448 | BC13: 448 | BD13: 448 | BE13: 533 | BF13: 690 | BG13: 690 | BH13: 643 | BI13: 690 | BJ13: 690 | BK13: 648 | BL13: 727 | BM13: 643 | BN13: 643 | BO13: 727 | BP13: 727 | BQ13: 727 | BR13: 727 | BS13: 448 | BT13: 448 | BU13: 448 | BV13: 448 | BW13: 448 | BX13: 533 | BY13: 533 | BZ13: 533 | CA13: 533 | CB13: 448 | CC13: 533 | CD13: 533 | CE13: 533 | CF13: 533 | CG13: 533 | CH13: 533 | CI13: 533
A14: 2625 | B14: 1.5 | D14: 3 | E14: 696 | F14: 696 | G14: 693 | H14: 696 | I14: 584 | J14: 584 | K14: 584 | L14: 584 | M14: 696 | N14: 693 | O14: 497 | P14: 497 | Q14: 497 | R14: 497 | S14: 497 | T14: 497 | U14: 497 | V14: 497 | W14: 497 | X14: 497 | Y14: 497 | Z14: 497 | AA14: 497 | AB14: 497 | AC14: 497 | AD14: 497 | AE14: 584 | AF14: 584 | AG14: 584 | AH14: 768 | AI14: 414 | AJ14: 414 | AK14: 414 | AL14: 414 | AM14: 414 | AN14: 422 | AO14: 422 | AP14: 422 | AQ14: 422 | AR14: 422 | AS14: 422 | AT14: 422 | AU14: 422 | AV14: 422 | AW14: 422 | AX14: 422 | AY14: 497 | AZ14: 497 | BA14: 497 | BB14: 497 | BC14: 497 | BD14: 497 | BE14: 584 | BF14: 734 | BG14: 734 | BH14: 693 | BI14: 734 | BJ14: 734 | BK14: 696 | BL14: 768 | BM14: 693 | BN14: 693 | BO14: 768 | BP14: 768 | BQ14: 768 | BR14: 768 | BS14: 497 | BT14: 497 | BU14: 497 | BV14: 497 | BW14: 497 | BX14: 584 | BY14: 584 | BZ14: 584 | CA14: 584 | CB14: 497 | CC14: 584 | CD14: 584 | CE14: 584 | CF14: 584 | CG14: 584 | CH14: 584 | CI14: 584
A15: 2800 | B15: 1.6 | C15: 4 | E15: 722 | F15: 722 | G15: 707 | H15: 722 | I15: 608 | J15: 608 | K15: 608 | L15: 608 | M15: 722 | N15: 707 | O15: 524 | P15: 524 | Q15: 524 | R15: 524 | S15: 524 | T15: 524 | U15: 524 | V15: 524 | W15: 524 | X15: 524 | Y15: 524 | Z15: 524 | AA15: 524 | AB15: 524 | AC15: 524 | AD15: 524 | AE15: 608 | AF15: 608 | AG15: 608 | AH15: 781 | AI15: 437 | AJ15: 437 | AK15: 437 | AL15: 437 | AM15: 437 | AN15: 447 | AO15: 447 | AP15: 447 | AQ15: 447 | AR15: 447 | AS15: 447 | AT15: 447 | AU15: 447 | AV15: 447 | AW15: 447 | AX15: 447 | AY15: 524 | AZ15: 524 | BA15: 524 | BB15: 524 | BC15: 524 | BD15: 524 | BE15: 608 | BF15: 748 | BG15: 748 | BH15: 707 | BI15: 748 | BJ15: 748 | BK15: 722 | BL15: 781 | BM15: 707 | BN15: 707 | BO15: 781 | BP15: 781 | BQ15: 781 | BR15: 781 | BS15: 524 | BT15: 524 | BU15: 524 | BV15: 524 | BW15: 524 | BX15: 608 | BY15: 608 | BZ15: 608 | CA15: 608 | CB15: 524 | CC15: 608 | CD15: 608 | CE15: 608 | CF15: 608 | CG15: 608 | CH15: 608 | CI15: 608
A16: 3500 | B16: 2 | C16: 5 | D16: 4 | E16: 761 | F16: 761 | G16: 772 | H16: 761 | I16: 649 | J16: 649 | K16: 649 | L16: 649 | M16: 761 | N16: 772 | O16: 564 | P16: 564 | Q16: 564 | R16: 564 | S16: 564 | T16: 564 | U16: 564 | V16: 564 | W16: 564 | X16: 564 | Y16: 564 | Z16: 564 | AA16: 564 | AB16: 564 | AC16: 564 | AD16: 564 | AE16: 649 | AF16: 649 | AG16: 649 | AH16: 834 | AI16: 479 | AJ16: 479 | AK16: 479 | AL16: 479 | AM16: 479 | AN16: 486 | AO16: 486 | AP16: 486 | AQ16: 486 | AR16: 486 | AS16: 486 | AT16: 486 | AU16: 486 | AV16: 486 | AW16: 486 | AX16: 486 | AY16: 564 | AZ16: 564 | BA16: 564 | BB16: 564 | BC16: 564 | BD16: 564 | BE16: 649 | BF16: 805 | BG16: 805 | BH16: 772 | BI16: 805 | BJ16: 805 | BK16: 761 | BL16: 834 | BM16: 772 | BN16: 772 | BO16: 834 | BP16: 834 | BQ16: 834 | BR16: 834 | BS16: 564 | BT16: 564 | BU16: 564 | BV16: 564 | BW16: 564 | BX16: 649 | BY16: 649 | BZ16: 649 | CA16: 649 | CB16: 564 | CC16: 649 | CD16: 649 | CE16: 649 | CF16: 649 | CG16: 649 | CH16: 649 | CI16: 649
A17: 4200 | B17: 2.4 | C17: 6 | E17: 809 | F17: 809 | G17: 820 | H17: 809 | I17: 706 | J17: 706 | K17: 706 | L17: 706 | M17: 809 | N17: 820 | O17: 626 | P17: 626 | Q17: 626 | R17: 626 | S17: 626 | T17: 626 | U17: 626 | V17: 626 | W17: 626 | X17: 626 | Y17: 626 | Z17: 626 | AA17: 626 | AB17: 626 | AC17: 626 | AD17: 626 | AE17: 706 | AF17: 706 | AG17: 706 | AH17: 869 | AI17: 549 | AJ17: 549 | AK17: 549 | AL17: 549 | AM17: 549 | AN17: 555 | AO17: 555 | AP17: 555 | AQ17: 555 | AR17: 555 | AS17: 555 | AT17: 555 | AU17: 555 | AV17: 555 | AW17: 555 | AX17: 555 | AY17: 626 | AZ17: 626 | BA17: 626 | BB17: 626 | BC17: 626 | BD17: 626 | BE17: 706 | BF17: 844 | BG17: 844 | BH17: 820 | BI17: 844 | BJ17: 844 | BK17: 809 | BL17: 869 | BM17: 820 | BN17: 820 | BO17: 869 | BP17: 869 | BQ17: 869 | BR17: 869 | BS17: 626 | BT17: 626 | BU17: 626 | BV17: 626 | BW17: 626 | BX17: 706 | BY17: 706 | BZ17: 706 | CA17: 706 | CB17: 626 | CC17: 706 | CD17: 706 | CE17: 706 | CF17: 706 | CG17: 706 | CH17: 706 | CI17: 706
A18: 4375 | B18: 2.5 | D18: 5 | E18: 825 | F18: 825 | G18: 834 | H18: 825 | I18: 719 | J18: 719 | K18: 719 | L18: 719 | M18: 825 | N18: 834 | O18: 641 | P18: 641 | Q18: 641 | R18: 641 | S18: 641 | T18: 641 | U18: 641 | V18: 641 | W18: 641 | X18: 641 | Y18: 641 | Z18: 641 | AA18: 641 | AB18: 641 | AC18: 641 | AD18: 641 | AE18: 719 | AF18: 719 | AG18: 719 | AH18: 881 | AI18: 587 | AJ18: 587 | AK18: 587 | AL18: 587 | AM18: 587 | AN18: 596 | AO18: 596 | AP18: 596 | AQ18: 596 | AR18: 596 | AS18: 596 | AT18: 596 | AU18: 596 | AV18: 596 | AW18: 596 | AX18: 596 | AY18: 641 | AZ18: 641 | BA18: 641 | BB18: 641 | BC18: 641 | BD18: 641 | BE18: 719 | BF18: 859 | BG18: 859 | BH18: 834 | BI18: 859 | BJ18: 859 | BK18: 825 | BL18: 881 | BM18: 834 | BN18: 834 | BO18: 881 | BP18: 881 | BQ18: 881 | BR18: 881 | BS18: 641 | BT18: 641 | BU18: 641 | BV18: 641 | BW18: 641 | BX18: 719 | BY18: 719 | BZ18: 719 | CA18: 719 | CB18: 641 | CC18: 719 | CD18: 719 | CE18: 719 | CF18: 719 | CG18: 719 | CH18: 719 | CI18: 719
A19: 4900 | B19: 2.8 | C19: 7 | E19: 861 | F19: 861 | G19: 882 | H19: 861 | I19: 769 | J19: 769 | K19: 769 | L19: 769 | M19: 861 | N19: 882 | O19: 677 | P19: 677 | Q19: 677 | R19: 677 | S19: 677 | T19: 677 | U19: 677 | V19: 677 | W19: 677 | X19: 677 | Y19: 677 | Z19: 677 | AA19: 677 | AB19: 677 | AC19: 677 | AD19: 677 | AE19: 769 | AF19: 769 | AG19: 769 | AH19: 921 | AI19: 623 | AJ19: 623 | AK19: 623 | AL19: 623 | AM19: 623 | AN19: 632 | AO19: 632 | AP19: 632 | AQ19: 632 | AR19: 632 | AS19: 632 | AT19: 632 | AU19: 632 | AV19: 632 | AW19: 632 | AX19: 632 | AY19: 677 | AZ19: 677 | BA19: 677 | BB19: 677 | BC19: 677 | BD19: 677 | BE19: 769 | BF19: 900 | BG19: 900 | BH19: 882 | BI19: 900 | BJ19: 900 | BK19: 861 | BL19: 921 | BM19: 882 | BN19: 882 | BO19: 921 | BP19: 921 | BQ19: 921 | BR19: 921 | BS19: 677 | BT19: 677 | BU19: 677 | BV19: 677 | BW19: 677 | BX19: 769 | BY19: 769 | BZ19: 769 | CA19: 769 | CB19: 677 | CC19: 769 | CD19: 769 | CE19: 769 | CF19: 769 | CG19: 769 | CH19: 769 | CI19: 769
